nohup: ignoring input
Watching for file changes with StatReloader
C:\Users\91853\OneDrive\Desktop\tasks\aibee_social\business\models.py changed, reloading.
DB_NAME socialdb
Performing system checks...

System check identified no issues (0 silenced).
February 19, 2025 - 11:31:02
Django version 5.1.6, using settings 'aibee_social.settings'
Starting development server at http://0.0.0.0:8000/
Quit the server with CTRL-BREAK.

Watching for file changes with StatReloader
C:\Users\91853\OneDrive\Desktop\tasks\aibee_social\business\models.py changed, reloading.
DB_NAME socialdb
Performing system checks...

System check identified no issues (0 silenced).
February 19, 2025 - 12:13:20
Django version 5.1.6, using settings 'aibee_social.settings'
Starting development server at http://0.0.0.0:8000/
Quit the server with CTRL-BREAK.

Watching for file changes with StatReloader
C:\Users\91853\OneDrive\Desktop\tasks\aibee_social\business\models.py changed, reloading.
DB_NAME socialdb
Performing system checks...

System check identified no issues (0 silenced).
February 19, 2025 - 12:13:33
Django version 5.1.6, using settings 'aibee_social.settings'
Starting development server at http://0.0.0.0:8000/
Quit the server with CTRL-BREAK.

Watching for file changes with StatReloader
C:\Users\91853\OneDrive\Desktop\tasks\aibee_social\business\models.py changed, reloading.
DB_NAME socialdb
Performing system checks...

System check identified no issues (0 silenced).
February 19, 2025 - 12:15:20
Django version 5.1.6, using settings 'aibee_social.settings'
Starting development server at http://0.0.0.0:8000/
Quit the server with CTRL-BREAK.

Watching for file changes with StatReloader
C:\Users\91853\OneDrive\Desktop\tasks\aibee_social\business\models.py changed, reloading.
DB_NAME socialdb
Performing system checks...

System check identified no issues (0 silenced).
February 19, 2025 - 12:16:56
Django version 5.1.6, using settings 'aibee_social.settings'
Starting development server at http://0.0.0.0:8000/
Quit the server with CTRL-BREAK.

Watching for file changes with StatReloader
C:\Users\91853\OneDrive\Desktop\tasks\aibee_social\business\migrations\0001_initial.py changed, reloading.
DB_NAME socialdb
Performing system checks...

System check identified no issues (0 silenced).
February 19, 2025 - 12:50:16
Django version 5.1.6, using settings 'aibee_social.settings'
Starting development server at http://0.0.0.0:8000/
Quit the server with CTRL-BREAK.

Watching for file changes with StatReloader
C:\Users\91853\OneDrive\Desktop\tasks\aibee_social\business\models.py changed, reloading.
DB_NAME socialdb
Performing system checks...

System check identified no issues (0 silenced).
February 19, 2025 - 12:52:50
Django version 5.1.6, using settings 'aibee_social.settings'
Starting development server at http://0.0.0.0:8000/
Quit the server with CTRL-BREAK.

Watching for file changes with StatReloader
C:\Users\91853\OneDrive\Desktop\tasks\aibee_social\business\models.py changed, reloading.
DB_NAME socialdb
Performing system checks...

System check identified no issues (0 silenced).
February 19, 2025 - 12:53:41
Django version 5.1.6, using settings 'aibee_social.settings'
Starting development server at http://0.0.0.0:8000/
Quit the server with CTRL-BREAK.

Watching for file changes with StatReloader
C:\Users\91853\OneDrive\Desktop\tasks\aibee_social\business\models.py changed, reloading.
DB_NAME socialdb
Performing system checks...

System check identified no issues (0 silenced).
February 19, 2025 - 12:53:51
Django version 5.1.6, using settings 'aibee_social.settings'
Starting development server at http://0.0.0.0:8000/
Quit the server with CTRL-BREAK.

Watching for file changes with StatReloader
C:\Users\91853\OneDrive\Desktop\tasks\aibee_social\business\models.py changed, reloading.
DB_NAME socialdb
Performing system checks...

System check identified no issues (0 silenced).
February 19, 2025 - 12:54:02
Django version 5.1.6, using settings 'aibee_social.settings'
Starting development server at http://0.0.0.0:8000/
Quit the server with CTRL-BREAK.

Watching for file changes with StatReloader
C:\Users\91853\OneDrive\Desktop\tasks\aibee_social\business\models.py changed, reloading.
DB_NAME socialdb
Performing system checks...

System check identified no issues (0 silenced).
February 19, 2025 - 12:54:19
Django version 5.1.6, using settings 'aibee_social.settings'
Starting development server at http://0.0.0.0:8000/
Quit the server with CTRL-BREAK.

Watching for file changes with StatReloader
C:\Users\91853\OneDrive\Desktop\tasks\aibee_social\business\models.py changed, reloading.
DB_NAME socialdb
Performing system checks...

System check identified no issues (0 silenced).
February 19, 2025 - 12:54:28
Django version 5.1.6, using settings 'aibee_social.settings'
Starting development server at http://0.0.0.0:8000/
Quit the server with CTRL-BREAK.

Watching for file changes with StatReloader
C:\Users\91853\OneDrive\Desktop\tasks\aibee_social\business\migrations\0001_initial.py changed, reloading.
DB_NAME socialdb
Performing system checks...

System check identified no issues (0 silenced).
February 19, 2025 - 12:54:44
Django version 5.1.6, using settings 'aibee_social.settings'
Starting development server at http://0.0.0.0:8000/
Quit the server with CTRL-BREAK.

Watching for file changes with StatReloader
C:\Users\91853\OneDrive\Desktop\tasks\aibee_social\business\migrations\0001_initial.py changed, reloading.
DB_NAME socialdb
Performing system checks...

System check identified no issues (0 silenced).
February 19, 2025 - 12:55:35
Django version 5.1.6, using settings 'aibee_social.settings'
Starting development server at http://0.0.0.0:8000/
Quit the server with CTRL-BREAK.

Watching for file changes with StatReloader
C:\Users\91853\OneDrive\Desktop\tasks\aibee_social\business\models.py changed, reloading.
DB_NAME socialdb
Performing system checks...

System check identified no issues (0 silenced).
February 19, 2025 - 12:56:39
Django version 5.1.6, using settings 'aibee_social.settings'
Starting development server at http://0.0.0.0:8000/
Quit the server with CTRL-BREAK.

Watching for file changes with StatReloader
C:\Users\91853\OneDrive\Desktop\tasks\aibee_social\business\models.py changed, reloading.
DB_NAME socialdb
Performing system checks...

System check identified no issues (0 silenced).
February 19, 2025 - 13:04:08
Django version 5.1.6, using settings 'aibee_social.settings'
Starting development server at http://0.0.0.0:8000/
Quit the server with CTRL-BREAK.

Watching for file changes with StatReloader
C:\Users\91853\OneDrive\Desktop\tasks\aibee_social\business\models.py changed, reloading.
DB_NAME socialdb
Performing system checks...

System check identified no issues (0 silenced).
February 19, 2025 - 13:07:40
Django version 5.1.6, using settings 'aibee_social.settings'
Starting development server at http://0.0.0.0:8000/
Quit the server with CTRL-BREAK.

Watching for file changes with StatReloader
C:\Users\91853\OneDrive\Desktop\tasks\aibee_social\business\models.py changed, reloading.
DB_NAME socialdb
Performing system checks...

System check identified no issues (0 silenced).
February 19, 2025 - 13:08:24
Django version 5.1.6, using settings 'aibee_social.settings'
Starting development server at http://0.0.0.0:8000/
Quit the server with CTRL-BREAK.

Watching for file changes with StatReloader
System check identified some issues:

WARNINGS:
business.contenttypes.behind_the_scenes_percentage: (fields.W122) 'max_length' is ignored when used with PositiveIntegerField.
	HINT: Remove 'max_length' from field
business.contenttypes.educational_content_percentage: (fields.W122) 'max_length' is ignored when used with PositiveIntegerField.
	HINT: Remove 'max_length' from field
business.contenttypes.inspirational_content_percentage: (fields.W122) 'max_length' is ignored when used with PositiveIntegerField.
	HINT: Remove 'max_length' from field
business.contenttypes.promotional_content_percentage: (fields.W122) 'max_length' is ignored when used with PositiveIntegerField.
	HINT: Remove 'max_length' from field

System check identified 4 issues (0 silenced).
C:\Users\91853\OneDrive\Desktop\tasks\aibee_social\business\models.py changed, reloading.
DB_NAME socialdb
Performing system checks...

February 19, 2025 - 13:09:24
Django version 5.1.6, using settings 'aibee_social.settings'
Starting development server at http://0.0.0.0:8000/
Quit the server with CTRL-BREAK.

Watching for file changes with StatReloader
C:\Users\91853\OneDrive\Desktop\tasks\aibee_social\business\models.py changed, reloading.
DB_NAME socialdb
Performing system checks...

System check identified no issues (0 silenced).
February 19, 2025 - 13:10:04
Django version 5.1.6, using settings 'aibee_social.settings'
Starting development server at http://0.0.0.0:8000/
Quit the server with CTRL-BREAK.

Watching for file changes with StatReloader
Exception in thread django-main-thread:
Traceback (most recent call last):
  File "C:\Users\91853\OneDrive\Desktop\tasks\aibee_social\env\Lib\site-packages\django\core\checks\urls.py", line 136, in check_custom_error_handlers
    handler = resolver.resolve_error_handler(status_code)
              ^^^^^^^^^^^^^^^^^^^^^^^^^^^^^^^^^^^^^^^^^^^
  File "C:\Users\91853\OneDrive\Desktop\tasks\aibee_social\env\Lib\site-packages\django\urls\resolvers.py", line 732, in resolve_error_handler
    callback = getattr(self.urlconf_module, "handler%s" % view_type, None)
                       ^^^^^^^^^^^^^^^^^^^
  File "C:\Users\91853\OneDrive\Desktop\tasks\aibee_social\env\Lib\site-packages\django\utils\functional.py", line 47, in __get__
    res = instance.__dict__[self.name] = self.func(instance)
                                         ^^^^^^^^^^^^^^^^^^^
  File "C:\Users\91853\OneDrive\Desktop\tasks\aibee_social\env\Lib\site-packages\django\urls\resolvers.py", line 711, in urlconf_module
    return import_module(self.urlconf_name)
           ^^^^^^^^^^^^^^^^^^^^^^^^^^^^^^^^
  File "C:\Users\91853\AppData\Local\Programs\Python\Python311\Lib\importlib\__init__.py", line 126, in import_module
    return _bootstrap._gcd_import(name[level:], package, level)
           ^^^^^^^^^^^^^^^^^^^^^^^^^^^^^^^^^^^^^^^^^^^^^^^^^^^^
  File "<frozen importlib._bootstrap>", line 1204, in _gcd_import
  File "<frozen importlib._bootstrap>", line 1176, in _find_and_load
  File "<frozen importlib._bootstrap>", line 1147, in _find_and_load_unlocked
  File "<frozen importlib._bootstrap>", line 690, in _load_unlocked
  File "<frozen importlib._bootstrap_external>", line 940, in exec_module
  File "<frozen importlib._bootstrap>", line 241, in _call_with_frames_removed
  File "C:\Users\91853\OneDrive\Desktop\tasks\aibee_social\aibee_social\urls.py", line 23, in <module>
    path('api/business/',include ('business.urls')),
                         ^^^^^^^^^^^^^^^^^^^^^^^^^
  File "C:\Users\91853\OneDrive\Desktop\tasks\aibee_social\env\Lib\site-packages\django\urls\conf.py", line 39, in include
    urlconf_module = import_module(urlconf_module)
                     ^^^^^^^^^^^^^^^^^^^^^^^^^^^^^
  File "C:\Users\91853\AppData\Local\Programs\Python\Python311\Lib\importlib\__init__.py", line 126, in import_module
    return _bootstrap._gcd_import(name[level:], package, level)
           ^^^^^^^^^^^^^^^^^^^^^^^^^^^^^^^^^^^^^^^^^^^^^^^^^^^^
  File "<frozen importlib._bootstrap>", line 1204, in _gcd_import
  File "<frozen importlib._bootstrap>", line 1176, in _find_and_load
  File "<frozen importlib._bootstrap>", line 1147, in _find_and_load_unlocked
  File "<frozen importlib._bootstrap>", line 690, in _load_unlocked
  File "<frozen importlib._bootstrap_external>", line 940, in exec_module
  File "<frozen importlib._bootstrap>", line 241, in _call_with_frames_removed
  File "C:\Users\91853\OneDrive\Desktop\tasks\aibee_social\business\urls.py", line 1, in <module>
    from business.views import (BusinessDetailsListCreate,BusinessProfileQuestionnaire,CommunicationPreferences,CommunicationStyle,
  File "C:\Users\91853\OneDrive\Desktop\tasks\aibee_social\business\views.py", line 2, in <module>
    from .serializers import (BusinessDetailsSerializer,BusinessProfileQuestionnaireSerializer,CommunicationPreferencesSerializer,
  File "C:\Users\91853\OneDrive\Desktop\tasks\aibee_social\business\serializers.py", line 3, in <module>
    from .models import (
ImportError: cannot import name 'visualstyle' from 'business.models' (C:\Users\91853\OneDrive\Desktop\tasks\aibee_social\business\models.py)

During handling of the above exception, another exception occurred:

Traceback (most recent call last):
  File "C:\Users\91853\AppData\Local\Programs\Python\Python311\Lib\threading.py", line 1038, in _bootstrap_inner
    self.run()
  File "C:\Users\91853\AppData\Local\Programs\Python\Python311\Lib\threading.py", line 975, in run
    self._target(*self._args, **self._kwargs)
  File "C:\Users\91853\OneDrive\Desktop\tasks\aibee_social\env\Lib\site-packages\django\utils\autoreload.py", line 64, in wrapper
    fn(*args, **kwargs)
  File "C:\Users\91853\OneDrive\Desktop\tasks\aibee_social\env\Lib\site-packages\django\core\management\commands\runserver.py", line 134, in inner_run
    self.check(display_num_errors=True)
  File "C:\Users\91853\OneDrive\Desktop\tasks\aibee_social\env\Lib\site-packages\django\core\management\base.py", line 486, in check
    all_issues = checks.run_checks(
                 ^^^^^^^^^^^^^^^^^^
  File "C:\Users\91853\OneDrive\Desktop\tasks\aibee_social\env\Lib\site-packages\django\core\checks\registry.py", line 88, in run_checks
    new_errors = check(app_configs=app_configs, databases=databases)
                 ^^^^^^^^^^^^^^^^^^^^^^^^^^^^^^^^^^^^^^^^^^^^^^^^^^^
  File "C:\Users\91853\OneDrive\Desktop\tasks\aibee_social\env\Lib\site-packages\django\core\checks\urls.py", line 138, in check_custom_error_handlers
    path = getattr(resolver.urlconf_module, "handler%s" % status_code)
                   ^^^^^^^^^^^^^^^^^^^^^^^
  File "C:\Users\91853\OneDrive\Desktop\tasks\aibee_social\env\Lib\site-packages\django\utils\functional.py", line 47, in __get__
    res = instance.__dict__[self.name] = self.func(instance)
                                         ^^^^^^^^^^^^^^^^^^^
  File "C:\Users\91853\OneDrive\Desktop\tasks\aibee_social\env\Lib\site-packages\django\urls\resolvers.py", line 711, in urlconf_module
    return import_module(self.urlconf_name)
           ^^^^^^^^^^^^^^^^^^^^^^^^^^^^^^^^
  File "C:\Users\91853\AppData\Local\Programs\Python\Python311\Lib\importlib\__init__.py", line 126, in import_module
    return _bootstrap._gcd_import(name[level:], package, level)
           ^^^^^^^^^^^^^^^^^^^^^^^^^^^^^^^^^^^^^^^^^^^^^^^^^^^^
  File "<frozen importlib._bootstrap>", line 1204, in _gcd_import
  File "<frozen importlib._bootstrap>", line 1176, in _find_and_load
  File "<frozen importlib._bootstrap>", line 1147, in _find_and_load_unlocked
  File "<frozen importlib._bootstrap>", line 690, in _load_unlocked
  File "<frozen importlib._bootstrap_external>", line 940, in exec_module
  File "<frozen importlib._bootstrap>", line 241, in _call_with_frames_removed
  File "C:\Users\91853\OneDrive\Desktop\tasks\aibee_social\aibee_social\urls.py", line 23, in <module>
    path('api/business/',include ('business.urls')),
                         ^^^^^^^^^^^^^^^^^^^^^^^^^
  File "C:\Users\91853\OneDrive\Desktop\tasks\aibee_social\env\Lib\site-packages\django\urls\conf.py", line 39, in include
    urlconf_module = import_module(urlconf_module)
                     ^^^^^^^^^^^^^^^^^^^^^^^^^^^^^
  File "C:\Users\91853\AppData\Local\Programs\Python\Python311\Lib\importlib\__init__.py", line 126, in import_module
    return _bootstrap._gcd_import(name[level:], package, level)
           ^^^^^^^^^^^^^^^^^^^^^^^^^^^^^^^^^^^^^^^^^^^^^^^^^^^^
  File "<frozen importlib._bootstrap>", line 1204, in _gcd_import
  File "<frozen importlib._bootstrap>", line 1176, in _find_and_load
  File "<frozen importlib._bootstrap>", line 1147, in _find_and_load_unlocked
  File "<frozen importlib._bootstrap>", line 690, in _load_unlocked
  File "<frozen importlib._bootstrap_external>", line 940, in exec_module
  File "<frozen importlib._bootstrap>", line 241, in _call_with_frames_removed
  File "C:\Users\91853\OneDrive\Desktop\tasks\aibee_social\business\urls.py", line 1, in <module>
    from business.views import (BusinessDetailsListCreate,BusinessProfileQuestionnaire,CommunicationPreferences,CommunicationStyle,
  File "C:\Users\91853\OneDrive\Desktop\tasks\aibee_social\business\views.py", line 2, in <module>
    from .serializers import (BusinessDetailsSerializer,BusinessProfileQuestionnaireSerializer,CommunicationPreferencesSerializer,
  File "C:\Users\91853\OneDrive\Desktop\tasks\aibee_social\business\serializers.py", line 3, in <module>
    from .models import (
ImportError: cannot import name 'visualstyle' from 'business.models' (C:\Users\91853\OneDrive\Desktop\tasks\aibee_social\business\models.py)
C:\Users\91853\OneDrive\Desktop\tasks\aibee_social\business\models.py changed, reloading.
DB_NAME socialdb
Performing system checks...

Watching for file changes with StatReloader
Exception in thread django-main-thread:
Traceback (most recent call last):
  File "C:\Users\91853\OneDrive\Desktop\tasks\aibee_social\env\Lib\site-packages\django\core\checks\urls.py", line 136, in check_custom_error_handlers
    handler = resolver.resolve_error_handler(status_code)
              ^^^^^^^^^^^^^^^^^^^^^^^^^^^^^^^^^^^^^^^^^^^
  File "C:\Users\91853\OneDrive\Desktop\tasks\aibee_social\env\Lib\site-packages\django\urls\resolvers.py", line 732, in resolve_error_handler
    callback = getattr(self.urlconf_module, "handler%s" % view_type, None)
                       ^^^^^^^^^^^^^^^^^^^
  File "C:\Users\91853\OneDrive\Desktop\tasks\aibee_social\env\Lib\site-packages\django\utils\functional.py", line 47, in __get__
    res = instance.__dict__[self.name] = self.func(instance)
                                         ^^^^^^^^^^^^^^^^^^^
  File "C:\Users\91853\OneDrive\Desktop\tasks\aibee_social\env\Lib\site-packages\django\urls\resolvers.py", line 711, in urlconf_module
    return import_module(self.urlconf_name)
           ^^^^^^^^^^^^^^^^^^^^^^^^^^^^^^^^
  File "C:\Users\91853\AppData\Local\Programs\Python\Python311\Lib\importlib\__init__.py", line 126, in import_module
    return _bootstrap._gcd_import(name[level:], package, level)
           ^^^^^^^^^^^^^^^^^^^^^^^^^^^^^^^^^^^^^^^^^^^^^^^^^^^^
  File "<frozen importlib._bootstrap>", line 1204, in _gcd_import
  File "<frozen importlib._bootstrap>", line 1176, in _find_and_load
  File "<frozen importlib._bootstrap>", line 1147, in _find_and_load_unlocked
  File "<frozen importlib._bootstrap>", line 690, in _load_unlocked
  File "<frozen importlib._bootstrap_external>", line 940, in exec_module
  File "<frozen importlib._bootstrap>", line 241, in _call_with_frames_removed
  File "C:\Users\91853\OneDrive\Desktop\tasks\aibee_social\aibee_social\urls.py", line 23, in <module>
    path('api/business/',include ('business.urls')),
                         ^^^^^^^^^^^^^^^^^^^^^^^^^
  File "C:\Users\91853\OneDrive\Desktop\tasks\aibee_social\env\Lib\site-packages\django\urls\conf.py", line 39, in include
    urlconf_module = import_module(urlconf_module)
                     ^^^^^^^^^^^^^^^^^^^^^^^^^^^^^
  File "C:\Users\91853\AppData\Local\Programs\Python\Python311\Lib\importlib\__init__.py", line 126, in import_module
    return _bootstrap._gcd_import(name[level:], package, level)
           ^^^^^^^^^^^^^^^^^^^^^^^^^^^^^^^^^^^^^^^^^^^^^^^^^^^^
  File "<frozen importlib._bootstrap>", line 1204, in _gcd_import
  File "<frozen importlib._bootstrap>", line 1176, in _find_and_load
  File "<frozen importlib._bootstrap>", line 1147, in _find_and_load_unlocked
  File "<frozen importlib._bootstrap>", line 690, in _load_unlocked
  File "<frozen importlib._bootstrap_external>", line 940, in exec_module
  File "<frozen importlib._bootstrap>", line 241, in _call_with_frames_removed
  File "C:\Users\91853\OneDrive\Desktop\tasks\aibee_social\business\urls.py", line 1, in <module>
    from business.views import (BusinessDetailsListCreate,BusinessProfileQuestionnaire,CommunicationPreferences,CommunicationStyle,
  File "C:\Users\91853\OneDrive\Desktop\tasks\aibee_social\business\views.py", line 2, in <module>
    from .serializers import (BusinessDetailsSerializer,BusinessProfileQuestionnaireSerializer,CommunicationPreferencesSerializer,
  File "C:\Users\91853\OneDrive\Desktop\tasks\aibee_social\business\serializers.py", line 3, in <module>
    from .models import (
ImportError: cannot import name 'visualstyle' from 'business.models' (C:\Users\91853\OneDrive\Desktop\tasks\aibee_social\business\models.py)

During handling of the above exception, another exception occurred:

Traceback (most recent call last):
  File "C:\Users\91853\AppData\Local\Programs\Python\Python311\Lib\threading.py", line 1038, in _bootstrap_inner
    self.run()
  File "C:\Users\91853\AppData\Local\Programs\Python\Python311\Lib\threading.py", line 975, in run
    self._target(*self._args, **self._kwargs)
  File "C:\Users\91853\OneDrive\Desktop\tasks\aibee_social\env\Lib\site-packages\django\utils\autoreload.py", line 64, in wrapper
    fn(*args, **kwargs)
  File "C:\Users\91853\OneDrive\Desktop\tasks\aibee_social\env\Lib\site-packages\django\core\management\commands\runserver.py", line 134, in inner_run
    self.check(display_num_errors=True)
  File "C:\Users\91853\OneDrive\Desktop\tasks\aibee_social\env\Lib\site-packages\django\core\management\base.py", line 486, in check
    all_issues = checks.run_checks(
                 ^^^^^^^^^^^^^^^^^^
  File "C:\Users\91853\OneDrive\Desktop\tasks\aibee_social\env\Lib\site-packages\django\core\checks\registry.py", line 88, in run_checks
    new_errors = check(app_configs=app_configs, databases=databases)
                 ^^^^^^^^^^^^^^^^^^^^^^^^^^^^^^^^^^^^^^^^^^^^^^^^^^^
  File "C:\Users\91853\OneDrive\Desktop\tasks\aibee_social\env\Lib\site-packages\django\core\checks\urls.py", line 138, in check_custom_error_handlers
    path = getattr(resolver.urlconf_module, "handler%s" % status_code)
                   ^^^^^^^^^^^^^^^^^^^^^^^
  File "C:\Users\91853\OneDrive\Desktop\tasks\aibee_social\env\Lib\site-packages\django\utils\functional.py", line 47, in __get__
    res = instance.__dict__[self.name] = self.func(instance)
                                         ^^^^^^^^^^^^^^^^^^^
  File "C:\Users\91853\OneDrive\Desktop\tasks\aibee_social\env\Lib\site-packages\django\urls\resolvers.py", line 711, in urlconf_module
    return import_module(self.urlconf_name)
           ^^^^^^^^^^^^^^^^^^^^^^^^^^^^^^^^
  File "C:\Users\91853\AppData\Local\Programs\Python\Python311\Lib\importlib\__init__.py", line 126, in import_module
    return _bootstrap._gcd_import(name[level:], package, level)
           ^^^^^^^^^^^^^^^^^^^^^^^^^^^^^^^^^^^^^^^^^^^^^^^^^^^^
  File "<frozen importlib._bootstrap>", line 1204, in _gcd_import
  File "<frozen importlib._bootstrap>", line 1176, in _find_and_load
  File "<frozen importlib._bootstrap>", line 1147, in _find_and_load_unlocked
  File "<frozen importlib._bootstrap>", line 690, in _load_unlocked
  File "<frozen importlib._bootstrap_external>", line 940, in exec_module
  File "<frozen importlib._bootstrap>", line 241, in _call_with_frames_removed
  File "C:\Users\91853\OneDrive\Desktop\tasks\aibee_social\aibee_social\urls.py", line 23, in <module>
    path('api/business/',include ('business.urls')),
                         ^^^^^^^^^^^^^^^^^^^^^^^^^
  File "C:\Users\91853\OneDrive\Desktop\tasks\aibee_social\env\Lib\site-packages\django\urls\conf.py", line 39, in include
    urlconf_module = import_module(urlconf_module)
                     ^^^^^^^^^^^^^^^^^^^^^^^^^^^^^
  File "C:\Users\91853\AppData\Local\Programs\Python\Python311\Lib\importlib\__init__.py", line 126, in import_module
    return _bootstrap._gcd_import(name[level:], package, level)
           ^^^^^^^^^^^^^^^^^^^^^^^^^^^^^^^^^^^^^^^^^^^^^^^^^^^^
  File "<frozen importlib._bootstrap>", line 1204, in _gcd_import
  File "<frozen importlib._bootstrap>", line 1176, in _find_and_load
  File "<frozen importlib._bootstrap>", line 1147, in _find_and_load_unlocked
  File "<frozen importlib._bootstrap>", line 690, in _load_unlocked
  File "<frozen importlib._bootstrap_external>", line 940, in exec_module
  File "<frozen importlib._bootstrap>", line 241, in _call_with_frames_removed
  File "C:\Users\91853\OneDrive\Desktop\tasks\aibee_social\business\urls.py", line 1, in <module>
    from business.views import (BusinessDetailsListCreate,BusinessProfileQuestionnaire,CommunicationPreferences,CommunicationStyle,
  File "C:\Users\91853\OneDrive\Desktop\tasks\aibee_social\business\views.py", line 2, in <module>
    from .serializers import (BusinessDetailsSerializer,BusinessProfileQuestionnaireSerializer,CommunicationPreferencesSerializer,
  File "C:\Users\91853\OneDrive\Desktop\tasks\aibee_social\business\serializers.py", line 3, in <module>
    from .models import (
ImportError: cannot import name 'visualstyle' from 'business.models' (C:\Users\91853\OneDrive\Desktop\tasks\aibee_social\business\models.py)
C:\Users\91853\OneDrive\Desktop\tasks\aibee_social\business\models.py changed, reloading.
DB_NAME socialdb
Performing system checks...

Watching for file changes with StatReloader
Exception in thread django-main-thread:
Traceback (most recent call last):
  File "C:\Users\91853\OneDrive\Desktop\tasks\aibee_social\env\Lib\site-packages\django\core\checks\urls.py", line 136, in check_custom_error_handlers
    handler = resolver.resolve_error_handler(status_code)
              ^^^^^^^^^^^^^^^^^^^^^^^^^^^^^^^^^^^^^^^^^^^
  File "C:\Users\91853\OneDrive\Desktop\tasks\aibee_social\env\Lib\site-packages\django\urls\resolvers.py", line 732, in resolve_error_handler
    callback = getattr(self.urlconf_module, "handler%s" % view_type, None)
                       ^^^^^^^^^^^^^^^^^^^
  File "C:\Users\91853\OneDrive\Desktop\tasks\aibee_social\env\Lib\site-packages\django\utils\functional.py", line 47, in __get__
    res = instance.__dict__[self.name] = self.func(instance)
                                         ^^^^^^^^^^^^^^^^^^^
  File "C:\Users\91853\OneDrive\Desktop\tasks\aibee_social\env\Lib\site-packages\django\urls\resolvers.py", line 711, in urlconf_module
    return import_module(self.urlconf_name)
           ^^^^^^^^^^^^^^^^^^^^^^^^^^^^^^^^
  File "C:\Users\91853\AppData\Local\Programs\Python\Python311\Lib\importlib\__init__.py", line 126, in import_module
    return _bootstrap._gcd_import(name[level:], package, level)
           ^^^^^^^^^^^^^^^^^^^^^^^^^^^^^^^^^^^^^^^^^^^^^^^^^^^^
  File "<frozen importlib._bootstrap>", line 1204, in _gcd_import
  File "<frozen importlib._bootstrap>", line 1176, in _find_and_load
  File "<frozen importlib._bootstrap>", line 1147, in _find_and_load_unlocked
  File "<frozen importlib._bootstrap>", line 690, in _load_unlocked
  File "<frozen importlib._bootstrap_external>", line 940, in exec_module
  File "<frozen importlib._bootstrap>", line 241, in _call_with_frames_removed
  File "C:\Users\91853\OneDrive\Desktop\tasks\aibee_social\aibee_social\urls.py", line 23, in <module>
    path('api/business/',include ('business.urls')),
                         ^^^^^^^^^^^^^^^^^^^^^^^^^
  File "C:\Users\91853\OneDrive\Desktop\tasks\aibee_social\env\Lib\site-packages\django\urls\conf.py", line 39, in include
    urlconf_module = import_module(urlconf_module)
                     ^^^^^^^^^^^^^^^^^^^^^^^^^^^^^
  File "C:\Users\91853\AppData\Local\Programs\Python\Python311\Lib\importlib\__init__.py", line 126, in import_module
    return _bootstrap._gcd_import(name[level:], package, level)
           ^^^^^^^^^^^^^^^^^^^^^^^^^^^^^^^^^^^^^^^^^^^^^^^^^^^^
  File "<frozen importlib._bootstrap>", line 1204, in _gcd_import
  File "<frozen importlib._bootstrap>", line 1176, in _find_and_load
  File "<frozen importlib._bootstrap>", line 1147, in _find_and_load_unlocked
  File "<frozen importlib._bootstrap>", line 690, in _load_unlocked
  File "<frozen importlib._bootstrap_external>", line 940, in exec_module
  File "<frozen importlib._bootstrap>", line 241, in _call_with_frames_removed
  File "C:\Users\91853\OneDrive\Desktop\tasks\aibee_social\business\urls.py", line 1, in <module>
    from business.views import (BusinessDetailsListCreate,BusinessProfileQuestionnaire,CommunicationPreferences,CommunicationStyle,
  File "C:\Users\91853\OneDrive\Desktop\tasks\aibee_social\business\views.py", line 2, in <module>
    from .serializers import (BusinessDetailsSerializer,BusinessProfileQuestionnaireSerializer,CommunicationPreferencesSerializer,
  File "C:\Users\91853\OneDrive\Desktop\tasks\aibee_social\business\serializers.py", line 3, in <module>
    from .models import (
ImportError: cannot import name 'visualstyle' from 'business.models' (C:\Users\91853\OneDrive\Desktop\tasks\aibee_social\business\models.py)

During handling of the above exception, another exception occurred:

Traceback (most recent call last):
  File "C:\Users\91853\AppData\Local\Programs\Python\Python311\Lib\threading.py", line 1038, in _bootstrap_inner
    self.run()
  File "C:\Users\91853\AppData\Local\Programs\Python\Python311\Lib\threading.py", line 975, in run
    self._target(*self._args, **self._kwargs)
  File "C:\Users\91853\OneDrive\Desktop\tasks\aibee_social\env\Lib\site-packages\django\utils\autoreload.py", line 64, in wrapper
    fn(*args, **kwargs)
  File "C:\Users\91853\OneDrive\Desktop\tasks\aibee_social\env\Lib\site-packages\django\core\management\commands\runserver.py", line 134, in inner_run
    self.check(display_num_errors=True)
  File "C:\Users\91853\OneDrive\Desktop\tasks\aibee_social\env\Lib\site-packages\django\core\management\base.py", line 486, in check
    all_issues = checks.run_checks(
                 ^^^^^^^^^^^^^^^^^^
  File "C:\Users\91853\OneDrive\Desktop\tasks\aibee_social\env\Lib\site-packages\django\core\checks\registry.py", line 88, in run_checks
    new_errors = check(app_configs=app_configs, databases=databases)
                 ^^^^^^^^^^^^^^^^^^^^^^^^^^^^^^^^^^^^^^^^^^^^^^^^^^^
  File "C:\Users\91853\OneDrive\Desktop\tasks\aibee_social\env\Lib\site-packages\django\core\checks\urls.py", line 138, in check_custom_error_handlers
    path = getattr(resolver.urlconf_module, "handler%s" % status_code)
                   ^^^^^^^^^^^^^^^^^^^^^^^
  File "C:\Users\91853\OneDrive\Desktop\tasks\aibee_social\env\Lib\site-packages\django\utils\functional.py", line 47, in __get__
    res = instance.__dict__[self.name] = self.func(instance)
                                         ^^^^^^^^^^^^^^^^^^^
  File "C:\Users\91853\OneDrive\Desktop\tasks\aibee_social\env\Lib\site-packages\django\urls\resolvers.py", line 711, in urlconf_module
    return import_module(self.urlconf_name)
           ^^^^^^^^^^^^^^^^^^^^^^^^^^^^^^^^
  File "C:\Users\91853\AppData\Local\Programs\Python\Python311\Lib\importlib\__init__.py", line 126, in import_module
    return _bootstrap._gcd_import(name[level:], package, level)
           ^^^^^^^^^^^^^^^^^^^^^^^^^^^^^^^^^^^^^^^^^^^^^^^^^^^^
  File "<frozen importlib._bootstrap>", line 1204, in _gcd_import
  File "<frozen importlib._bootstrap>", line 1176, in _find_and_load
  File "<frozen importlib._bootstrap>", line 1147, in _find_and_load_unlocked
  File "<frozen importlib._bootstrap>", line 690, in _load_unlocked
  File "<frozen importlib._bootstrap_external>", line 940, in exec_module
  File "<frozen importlib._bootstrap>", line 241, in _call_with_frames_removed
  File "C:\Users\91853\OneDrive\Desktop\tasks\aibee_social\aibee_social\urls.py", line 23, in <module>
    path('api/business/',include ('business.urls')),
                         ^^^^^^^^^^^^^^^^^^^^^^^^^
  File "C:\Users\91853\OneDrive\Desktop\tasks\aibee_social\env\Lib\site-packages\django\urls\conf.py", line 39, in include
    urlconf_module = import_module(urlconf_module)
                     ^^^^^^^^^^^^^^^^^^^^^^^^^^^^^
  File "C:\Users\91853\AppData\Local\Programs\Python\Python311\Lib\importlib\__init__.py", line 126, in import_module
    return _bootstrap._gcd_import(name[level:], package, level)
           ^^^^^^^^^^^^^^^^^^^^^^^^^^^^^^^^^^^^^^^^^^^^^^^^^^^^
  File "<frozen importlib._bootstrap>", line 1204, in _gcd_import
  File "<frozen importlib._bootstrap>", line 1176, in _find_and_load
  File "<frozen importlib._bootstrap>", line 1147, in _find_and_load_unlocked
  File "<frozen importlib._bootstrap>", line 690, in _load_unlocked
  File "<frozen importlib._bootstrap_external>", line 940, in exec_module
  File "<frozen importlib._bootstrap>", line 241, in _call_with_frames_removed
  File "C:\Users\91853\OneDrive\Desktop\tasks\aibee_social\business\urls.py", line 1, in <module>
    from business.views import (BusinessDetailsListCreate,BusinessProfileQuestionnaire,CommunicationPreferences,CommunicationStyle,
  File "C:\Users\91853\OneDrive\Desktop\tasks\aibee_social\business\views.py", line 2, in <module>
    from .serializers import (BusinessDetailsSerializer,BusinessProfileQuestionnaireSerializer,CommunicationPreferencesSerializer,
  File "C:\Users\91853\OneDrive\Desktop\tasks\aibee_social\business\serializers.py", line 3, in <module>
    from .models import (
ImportError: cannot import name 'visualstyle' from 'business.models' (C:\Users\91853\OneDrive\Desktop\tasks\aibee_social\business\models.py)
C:\Users\91853\OneDrive\Desktop\tasks\aibee_social\business\serializers.py changed, reloading.
DB_NAME socialdb
Performing system checks...

Watching for file changes with StatReloader
Exception in thread django-main-thread:
Traceback (most recent call last):
  File "C:\Users\91853\OneDrive\Desktop\tasks\aibee_social\env\Lib\site-packages\django\core\checks\urls.py", line 136, in check_custom_error_handlers
    handler = resolver.resolve_error_handler(status_code)
              ^^^^^^^^^^^^^^^^^^^^^^^^^^^^^^^^^^^^^^^^^^^
  File "C:\Users\91853\OneDrive\Desktop\tasks\aibee_social\env\Lib\site-packages\django\urls\resolvers.py", line 732, in resolve_error_handler
    callback = getattr(self.urlconf_module, "handler%s" % view_type, None)
                       ^^^^^^^^^^^^^^^^^^^
  File "C:\Users\91853\OneDrive\Desktop\tasks\aibee_social\env\Lib\site-packages\django\utils\functional.py", line 47, in __get__
    res = instance.__dict__[self.name] = self.func(instance)
                                         ^^^^^^^^^^^^^^^^^^^
  File "C:\Users\91853\OneDrive\Desktop\tasks\aibee_social\env\Lib\site-packages\django\urls\resolvers.py", line 711, in urlconf_module
    return import_module(self.urlconf_name)
           ^^^^^^^^^^^^^^^^^^^^^^^^^^^^^^^^
  File "C:\Users\91853\AppData\Local\Programs\Python\Python311\Lib\importlib\__init__.py", line 126, in import_module
    return _bootstrap._gcd_import(name[level:], package, level)
           ^^^^^^^^^^^^^^^^^^^^^^^^^^^^^^^^^^^^^^^^^^^^^^^^^^^^
  File "<frozen importlib._bootstrap>", line 1204, in _gcd_import
  File "<frozen importlib._bootstrap>", line 1176, in _find_and_load
  File "<frozen importlib._bootstrap>", line 1147, in _find_and_load_unlocked
  File "<frozen importlib._bootstrap>", line 690, in _load_unlocked
  File "<frozen importlib._bootstrap_external>", line 940, in exec_module
  File "<frozen importlib._bootstrap>", line 241, in _call_with_frames_removed
  File "C:\Users\91853\OneDrive\Desktop\tasks\aibee_social\aibee_social\urls.py", line 23, in <module>
    path('api/business/',include ('business.urls')),
                         ^^^^^^^^^^^^^^^^^^^^^^^^^
  File "C:\Users\91853\OneDrive\Desktop\tasks\aibee_social\env\Lib\site-packages\django\urls\conf.py", line 39, in include
    urlconf_module = import_module(urlconf_module)
                     ^^^^^^^^^^^^^^^^^^^^^^^^^^^^^
  File "C:\Users\91853\AppData\Local\Programs\Python\Python311\Lib\importlib\__init__.py", line 126, in import_module
    return _bootstrap._gcd_import(name[level:], package, level)
           ^^^^^^^^^^^^^^^^^^^^^^^^^^^^^^^^^^^^^^^^^^^^^^^^^^^^
  File "<frozen importlib._bootstrap>", line 1204, in _gcd_import
  File "<frozen importlib._bootstrap>", line 1176, in _find_and_load
  File "<frozen importlib._bootstrap>", line 1147, in _find_and_load_unlocked
  File "<frozen importlib._bootstrap>", line 690, in _load_unlocked
  File "<frozen importlib._bootstrap_external>", line 940, in exec_module
  File "<frozen importlib._bootstrap>", line 241, in _call_with_frames_removed
  File "C:\Users\91853\OneDrive\Desktop\tasks\aibee_social\business\urls.py", line 1, in <module>
    from business.views import (BusinessDetailsListCreate,BusinessProfileQuestionnaire,CommunicationPreferences,CommunicationStyle,
  File "C:\Users\91853\OneDrive\Desktop\tasks\aibee_social\business\views.py", line 4, in <module>
    from business.models import (BusinessDetails,CommunicationPreferences,CommunicationStyle,contenttypes,visualstyle,successMetrics
ImportError: cannot import name 'visualstyle' from 'business.models' (C:\Users\91853\OneDrive\Desktop\tasks\aibee_social\business\models.py)

During handling of the above exception, another exception occurred:

Traceback (most recent call last):
  File "C:\Users\91853\AppData\Local\Programs\Python\Python311\Lib\threading.py", line 1038, in _bootstrap_inner
    self.run()
  File "C:\Users\91853\AppData\Local\Programs\Python\Python311\Lib\threading.py", line 975, in run
    self._target(*self._args, **self._kwargs)
  File "C:\Users\91853\OneDrive\Desktop\tasks\aibee_social\env\Lib\site-packages\django\utils\autoreload.py", line 64, in wrapper
    fn(*args, **kwargs)
  File "C:\Users\91853\OneDrive\Desktop\tasks\aibee_social\env\Lib\site-packages\django\core\management\commands\runserver.py", line 134, in inner_run
    self.check(display_num_errors=True)
  File "C:\Users\91853\OneDrive\Desktop\tasks\aibee_social\env\Lib\site-packages\django\core\management\base.py", line 486, in check
    all_issues = checks.run_checks(
                 ^^^^^^^^^^^^^^^^^^
  File "C:\Users\91853\OneDrive\Desktop\tasks\aibee_social\env\Lib\site-packages\django\core\checks\registry.py", line 88, in run_checks
    new_errors = check(app_configs=app_configs, databases=databases)
                 ^^^^^^^^^^^^^^^^^^^^^^^^^^^^^^^^^^^^^^^^^^^^^^^^^^^
  File "C:\Users\91853\OneDrive\Desktop\tasks\aibee_social\env\Lib\site-packages\django\core\checks\urls.py", line 138, in check_custom_error_handlers
    path = getattr(resolver.urlconf_module, "handler%s" % status_code)
                   ^^^^^^^^^^^^^^^^^^^^^^^
  File "C:\Users\91853\OneDrive\Desktop\tasks\aibee_social\env\Lib\site-packages\django\utils\functional.py", line 47, in __get__
    res = instance.__dict__[self.name] = self.func(instance)
                                         ^^^^^^^^^^^^^^^^^^^
  File "C:\Users\91853\OneDrive\Desktop\tasks\aibee_social\env\Lib\site-packages\django\urls\resolvers.py", line 711, in urlconf_module
    return import_module(self.urlconf_name)
           ^^^^^^^^^^^^^^^^^^^^^^^^^^^^^^^^
  File "C:\Users\91853\AppData\Local\Programs\Python\Python311\Lib\importlib\__init__.py", line 126, in import_module
    return _bootstrap._gcd_import(name[level:], package, level)
           ^^^^^^^^^^^^^^^^^^^^^^^^^^^^^^^^^^^^^^^^^^^^^^^^^^^^
  File "<frozen importlib._bootstrap>", line 1204, in _gcd_import
  File "<frozen importlib._bootstrap>", line 1176, in _find_and_load
  File "<frozen importlib._bootstrap>", line 1147, in _find_and_load_unlocked
  File "<frozen importlib._bootstrap>", line 690, in _load_unlocked
  File "<frozen importlib._bootstrap_external>", line 940, in exec_module
  File "<frozen importlib._bootstrap>", line 241, in _call_with_frames_removed
  File "C:\Users\91853\OneDrive\Desktop\tasks\aibee_social\aibee_social\urls.py", line 23, in <module>
    path('api/business/',include ('business.urls')),
                         ^^^^^^^^^^^^^^^^^^^^^^^^^
  File "C:\Users\91853\OneDrive\Desktop\tasks\aibee_social\env\Lib\site-packages\django\urls\conf.py", line 39, in include
    urlconf_module = import_module(urlconf_module)
                     ^^^^^^^^^^^^^^^^^^^^^^^^^^^^^
  File "C:\Users\91853\AppData\Local\Programs\Python\Python311\Lib\importlib\__init__.py", line 126, in import_module
    return _bootstrap._gcd_import(name[level:], package, level)
           ^^^^^^^^^^^^^^^^^^^^^^^^^^^^^^^^^^^^^^^^^^^^^^^^^^^^
  File "<frozen importlib._bootstrap>", line 1204, in _gcd_import
  File "<frozen importlib._bootstrap>", line 1176, in _find_and_load
  File "<frozen importlib._bootstrap>", line 1147, in _find_and_load_unlocked
  File "<frozen importlib._bootstrap>", line 690, in _load_unlocked
  File "<frozen importlib._bootstrap_external>", line 940, in exec_module
  File "<frozen importlib._bootstrap>", line 241, in _call_with_frames_removed
  File "C:\Users\91853\OneDrive\Desktop\tasks\aibee_social\business\urls.py", line 1, in <module>
    from business.views import (BusinessDetailsListCreate,BusinessProfileQuestionnaire,CommunicationPreferences,CommunicationStyle,
  File "C:\Users\91853\OneDrive\Desktop\tasks\aibee_social\business\views.py", line 4, in <module>
    from business.models import (BusinessDetails,CommunicationPreferences,CommunicationStyle,contenttypes,visualstyle,successMetrics
ImportError: cannot import name 'visualstyle' from 'business.models' (C:\Users\91853\OneDrive\Desktop\tasks\aibee_social\business\models.py)
C:\Users\91853\OneDrive\Desktop\tasks\aibee_social\business\views.py changed, reloading.
DB_NAME socialdb
Performing system checks...

Watching for file changes with StatReloader
Exception in thread django-main-thread:
Traceback (most recent call last):
  File "C:\Users\91853\AppData\Local\Programs\Python\Python311\Lib\threading.py", line 1038, in _bootstrap_inner
    self.run()
  File "C:\Users\91853\AppData\Local\Programs\Python\Python311\Lib\threading.py", line 975, in run
    self._target(*self._args, **self._kwargs)
  File "C:\Users\91853\OneDrive\Desktop\tasks\aibee_social\env\Lib\site-packages\django\utils\autoreload.py", line 64, in wrapper
    fn(*args, **kwargs)
  File "C:\Users\91853\OneDrive\Desktop\tasks\aibee_social\env\Lib\site-packages\django\core\management\commands\runserver.py", line 134, in inner_run
    self.check(display_num_errors=True)
  File "C:\Users\91853\OneDrive\Desktop\tasks\aibee_social\env\Lib\site-packages\django\core\management\base.py", line 563, in check
    raise SystemCheckError(msg)
django.core.management.base.SystemCheckError: SystemCheckError: System check identified some issues:

ERRORS:
business.VisualStyle.accent_color: (fields.E009) 'max_length' is too small to fit the longest value in 'choices' (16 characters).
business.VisualStyle.primary_color: (fields.E009) 'max_length' is too small to fit the longest value in 'choices' (16 characters).
business.VisualStyle.secondary_color: (fields.E009) 'max_length' is too small to fit the longest value in 'choices' (16 characters).

System check identified 3 issues (0 silenced).
C:\Users\91853\OneDrive\Desktop\tasks\aibee_social\business\models.py changed, reloading.
DB_NAME socialdb
Performing system checks...

Watching for file changes with StatReloader
C:\Users\91853\OneDrive\Desktop\tasks\aibee_social\business\models.py changed, reloading.
DB_NAME socialdb
Performing system checks...

System check identified no issues (0 silenced).
February 19, 2025 - 13:26:30
Django version 5.1.6, using settings 'aibee_social.settings'
Starting development server at http://0.0.0.0:8000/
Quit the server with CTRL-BREAK.

Watching for file changes with StatReloader
C:\Users\91853\OneDrive\Desktop\tasks\aibee_social\business\models.py changed, reloading.
DB_NAME socialdb
Performing system checks...

System check identified no issues (0 silenced).
February 19, 2025 - 13:30:42
Django version 5.1.6, using settings 'aibee_social.settings'
Starting development server at http://0.0.0.0:8000/
Quit the server with CTRL-BREAK.

Watching for file changes with StatReloader
C:\Users\91853\OneDrive\Desktop\tasks\aibee_social\business\migrations\0001_initial.py changed, reloading.
DB_NAME socialdb
Performing system checks...

System check identified no issues (0 silenced).
February 19, 2025 - 13:34:05
Django version 5.1.6, using settings 'aibee_social.settings'
Starting development server at http://0.0.0.0:8000/
Quit the server with CTRL-BREAK.

Watching for file changes with StatReloader
C:\Users\91853\OneDrive\Desktop\tasks\aibee_social\business\models.py changed, reloading.
DB_NAME socialdb
Performing system checks...

System check identified no issues (0 silenced).
February 19, 2025 - 13:36:38
Django version 5.1.6, using settings 'aibee_social.settings'
Starting development server at http://0.0.0.0:8000/
Quit the server with CTRL-BREAK.

Watching for file changes with StatReloader
C:\Users\91853\OneDrive\Desktop\tasks\aibee_social\business\migrations\0001_initial.py changed, reloading.
DB_NAME socialdb
Performing system checks...

System check identified no issues (0 silenced).
February 19, 2025 - 13:37:47
Django version 5.1.6, using settings 'aibee_social.settings'
Starting development server at http://0.0.0.0:8000/
Quit the server with CTRL-BREAK.

Watching for file changes with StatReloader
C:\Users\91853\OneDrive\Desktop\tasks\aibee_social\business\migrations\0001_initial.py changed, reloading.
DB_NAME socialdb
Performing system checks...

System check identified no issues (0 silenced).
February 19, 2025 - 13:45:10
Django version 5.1.6, using settings 'aibee_social.settings'
Starting development server at http://0.0.0.0:8000/
Quit the server with CTRL-BREAK.

Watching for file changes with StatReloader
C:\Users\91853\OneDrive\Desktop\tasks\aibee_social\business\models.py changed, reloading.
DB_NAME socialdb
Performing system checks...

System check identified no issues (0 silenced).
February 19, 2025 - 13:48:38
Django version 5.1.6, using settings 'aibee_social.settings'
Starting development server at http://0.0.0.0:8000/
Quit the server with CTRL-BREAK.

Watching for file changes with StatReloader
C:\Users\91853\OneDrive\Desktop\tasks\aibee_social\business\views.py changed, reloading.
DB_NAME socialdb
Performing system checks...

System check identified no issues (0 silenced).
February 19, 2025 - 13:52:00
Django version 5.1.6, using settings 'aibee_social.settings'
Starting development server at http://0.0.0.0:8000/
Quit the server with CTRL-BREAK.

Watching for file changes with StatReloader
Exception in thread django-main-thread:
Traceback (most recent call last):
  File "C:\Users\91853\AppData\Local\Programs\Python\Python311\Lib\threading.py", line 1038, in _bootstrap_inner
    self.run()
  File "C:\Users\91853\AppData\Local\Programs\Python\Python311\Lib\threading.py", line 975, in run
    self._target(*self._args, **self._kwargs)
  File "C:\Users\91853\OneDrive\Desktop\tasks\aibee_social\env\Lib\site-packages\django\utils\autoreload.py", line 64, in wrapper
    fn(*args, **kwargs)
  File "C:\Users\91853\OneDrive\Desktop\tasks\aibee_social\env\Lib\site-packages\django\core\management\commands\runserver.py", line 134, in inner_run
    self.check(display_num_errors=True)
  File "C:\Users\91853\OneDrive\Desktop\tasks\aibee_social\env\Lib\site-packages\django\core\management\base.py", line 486, in check
    all_issues = checks.run_checks(
                 ^^^^^^^^^^^^^^^^^^
  File "C:\Users\91853\OneDrive\Desktop\tasks\aibee_social\env\Lib\site-packages\django\core\checks\registry.py", line 88, in run_checks
    new_errors = check(app_configs=app_configs, databases=databases)
                 ^^^^^^^^^^^^^^^^^^^^^^^^^^^^^^^^^^^^^^^^^^^^^^^^^^^
  File "C:\Users\91853\OneDrive\Desktop\tasks\aibee_social\env\Lib\site-packages\django\core\checks\urls.py", line 136, in check_custom_error_handlers
    handler = resolver.resolve_error_handler(status_code)
              ^^^^^^^^^^^^^^^^^^^^^^^^^^^^^^^^^^^^^^^^^^^
  File "C:\Users\91853\OneDrive\Desktop\tasks\aibee_social\env\Lib\site-packages\django\urls\resolvers.py", line 732, in resolve_error_handler
    callback = getattr(self.urlconf_module, "handler%s" % view_type, None)
                       ^^^^^^^^^^^^^^^^^^^
  File "C:\Users\91853\OneDrive\Desktop\tasks\aibee_social\env\Lib\site-packages\django\utils\functional.py", line 47, in __get__
    res = instance.__dict__[self.name] = self.func(instance)
                                         ^^^^^^^^^^^^^^^^^^^
  File "C:\Users\91853\OneDrive\Desktop\tasks\aibee_social\env\Lib\site-packages\django\urls\resolvers.py", line 711, in urlconf_module
    return import_module(self.urlconf_name)
           ^^^^^^^^^^^^^^^^^^^^^^^^^^^^^^^^
  File "C:\Users\91853\AppData\Local\Programs\Python\Python311\Lib\importlib\__init__.py", line 126, in import_module
    return _bootstrap._gcd_import(name[level:], package, level)
           ^^^^^^^^^^^^^^^^^^^^^^^^^^^^^^^^^^^^^^^^^^^^^^^^^^^^
  File "<frozen importlib._bootstrap>", line 1204, in _gcd_import
  File "<frozen importlib._bootstrap>", line 1176, in _find_and_load
  File "<frozen importlib._bootstrap>", line 1147, in _find_and_load_unlocked
  File "<frozen importlib._bootstrap>", line 690, in _load_unlocked
  File "<frozen importlib._bootstrap_external>", line 940, in exec_module
  File "<frozen importlib._bootstrap>", line 241, in _call_with_frames_removed
  File "C:\Users\91853\OneDrive\Desktop\tasks\aibee_social\aibee_social\urls.py", line 23, in <module>
    path('api/business/',include ('business.urls')),
                         ^^^^^^^^^^^^^^^^^^^^^^^^^
  File "C:\Users\91853\OneDrive\Desktop\tasks\aibee_social\env\Lib\site-packages\django\urls\conf.py", line 39, in include
    urlconf_module = import_module(urlconf_module)
                     ^^^^^^^^^^^^^^^^^^^^^^^^^^^^^
  File "C:\Users\91853\AppData\Local\Programs\Python\Python311\Lib\importlib\__init__.py", line 126, in import_module
    return _bootstrap._gcd_import(name[level:], package, level)
           ^^^^^^^^^^^^^^^^^^^^^^^^^^^^^^^^^^^^^^^^^^^^^^^^^^^^
  File "<frozen importlib._bootstrap>", line 1204, in _gcd_import
  File "<frozen importlib._bootstrap>", line 1176, in _find_and_load
  File "<frozen importlib._bootstrap>", line 1147, in _find_and_load_unlocked
  File "<frozen importlib._bootstrap>", line 690, in _load_unlocked
  File "<frozen importlib._bootstrap_external>", line 940, in exec_module
  File "<frozen importlib._bootstrap>", line 241, in _call_with_frames_removed
  File "C:\Users\91853\OneDrive\Desktop\tasks\aibee_social\business\urls.py", line 1, in <module>
    from business.views import (BusinessDetailsListCreate,BusinessProfileQuestionnaire,CommunicationPreferences,CommunicationStyle,
  File "C:\Users\91853\OneDrive\Desktop\tasks\aibee_social\business\views.py", line 22
    def put(self, request):
                           ^
IndentationError: unindent does not match any outer indentation level
C:\Users\91853\OneDrive\Desktop\tasks\aibee_social\business\views.py changed, reloading.
DB_NAME socialdb
Performing system checks...

Watching for file changes with StatReloader
C:\Users\91853\OneDrive\Desktop\tasks\aibee_social\business\views.py changed, reloading.
DB_NAME socialdb
Performing system checks...

System check identified no issues (0 silenced).
February 19, 2025 - 17:03:41
Django version 5.1.6, using settings 'aibee_social.settings'
Starting development server at http://0.0.0.0:8000/
Quit the server with CTRL-BREAK.

Watching for file changes with StatReloader
C:\Users\91853\OneDrive\Desktop\tasks\aibee_social\business\views.py changed, reloading.
DB_NAME socialdb
Performing system checks...

System check identified no issues (0 silenced).
February 19, 2025 - 17:04:27
Django version 5.1.6, using settings 'aibee_social.settings'
Starting development server at http://0.0.0.0:8000/
Quit the server with CTRL-BREAK.

Watching for file changes with StatReloader
C:\Users\91853\OneDrive\Desktop\tasks\aibee_social\business\views.py changed, reloading.
DB_NAME socialdb
Performing system checks...

System check identified no issues (0 silenced).
February 19, 2025 - 17:04:48
Django version 5.1.6, using settings 'aibee_social.settings'
Starting development server at http://0.0.0.0:8000/
Quit the server with CTRL-BREAK.

Watching for file changes with StatReloader
C:\Users\91853\OneDrive\Desktop\tasks\aibee_social\business\views.py changed, reloading.
DB_NAME socialdb
Performing system checks...

System check identified no issues (0 silenced).
February 19, 2025 - 17:05:41
Django version 5.1.6, using settings 'aibee_social.settings'
Starting development server at http://0.0.0.0:8000/
Quit the server with CTRL-BREAK.

Watching for file changes with StatReloader
C:\Users\91853\OneDrive\Desktop\tasks\aibee_social\business\views.py changed, reloading.
DB_NAME socialdb
Performing system checks...

System check identified no issues (0 silenced).
February 19, 2025 - 17:06:03
Django version 5.1.6, using settings 'aibee_social.settings'
Starting development server at http://0.0.0.0:8000/
Quit the server with CTRL-BREAK.

Watching for file changes with StatReloader
C:\Users\91853\OneDrive\Desktop\tasks\aibee_social\business\views.py changed, reloading.
DB_NAME socialdb
Performing system checks...

System check identified no issues (0 silenced).
February 19, 2025 - 17:06:30
Django version 5.1.6, using settings 'aibee_social.settings'
Starting development server at http://0.0.0.0:8000/
Quit the server with CTRL-BREAK.

Watching for file changes with StatReloader
C:\Users\91853\OneDrive\Desktop\tasks\aibee_social\business\views.py changed, reloading.
DB_NAME socialdb
Performing system checks...

System check identified no issues (0 silenced).
February 19, 2025 - 17:12:36
Django version 5.1.6, using settings 'aibee_social.settings'
Starting development server at http://0.0.0.0:8000/
Quit the server with CTRL-BREAK.

Watching for file changes with StatReloader
C:\Users\91853\OneDrive\Desktop\tasks\aibee_social\business\urls.py changed, reloading.
DB_NAME socialdb
Performing system checks...

System check identified no issues (0 silenced).
February 19, 2025 - 17:12:50
Django version 5.1.6, using settings 'aibee_social.settings'
Starting development server at http://0.0.0.0:8000/
Quit the server with CTRL-BREAK.

Watching for file changes with StatReloader
Exception in thread django-main-thread:
Traceback (most recent call last):
  File "C:\Users\91853\AppData\Local\Programs\Python\Python311\Lib\threading.py", line 1038, in _bootstrap_inner
    self.run()
  File "C:\Users\91853\AppData\Local\Programs\Python\Python311\Lib\threading.py", line 975, in run
    self._target(*self._args, **self._kwargs)
  File "C:\Users\91853\OneDrive\Desktop\tasks\aibee_social\env\Lib\site-packages\django\utils\autoreload.py", line 64, in wrapper
    fn(*args, **kwargs)
  File "C:\Users\91853\OneDrive\Desktop\tasks\aibee_social\env\Lib\site-packages\django\core\management\commands\runserver.py", line 134, in inner_run
    self.check(display_num_errors=True)
  File "C:\Users\91853\OneDrive\Desktop\tasks\aibee_social\env\Lib\site-packages\django\core\management\base.py", line 486, in check
    all_issues = checks.run_checks(
                 ^^^^^^^^^^^^^^^^^^
  File "C:\Users\91853\OneDrive\Desktop\tasks\aibee_social\env\Lib\site-packages\django\core\checks\registry.py", line 88, in run_checks
    new_errors = check(app_configs=app_configs, databases=databases)
                 ^^^^^^^^^^^^^^^^^^^^^^^^^^^^^^^^^^^^^^^^^^^^^^^^^^^
  File "C:\Users\91853\OneDrive\Desktop\tasks\aibee_social\env\Lib\site-packages\django\core\checks\urls.py", line 136, in check_custom_error_handlers
    handler = resolver.resolve_error_handler(status_code)
              ^^^^^^^^^^^^^^^^^^^^^^^^^^^^^^^^^^^^^^^^^^^
  File "C:\Users\91853\OneDrive\Desktop\tasks\aibee_social\env\Lib\site-packages\django\urls\resolvers.py", line 732, in resolve_error_handler
    callback = getattr(self.urlconf_module, "handler%s" % view_type, None)
                       ^^^^^^^^^^^^^^^^^^^
  File "C:\Users\91853\OneDrive\Desktop\tasks\aibee_social\env\Lib\site-packages\django\utils\functional.py", line 47, in __get__
    res = instance.__dict__[self.name] = self.func(instance)
                                         ^^^^^^^^^^^^^^^^^^^
  File "C:\Users\91853\OneDrive\Desktop\tasks\aibee_social\env\Lib\site-packages\django\urls\resolvers.py", line 711, in urlconf_module
    return import_module(self.urlconf_name)
           ^^^^^^^^^^^^^^^^^^^^^^^^^^^^^^^^
  File "C:\Users\91853\AppData\Local\Programs\Python\Python311\Lib\importlib\__init__.py", line 126, in import_module
    return _bootstrap._gcd_import(name[level:], package, level)
           ^^^^^^^^^^^^^^^^^^^^^^^^^^^^^^^^^^^^^^^^^^^^^^^^^^^^
  File "<frozen importlib._bootstrap>", line 1204, in _gcd_import
  File "<frozen importlib._bootstrap>", line 1176, in _find_and_load
  File "<frozen importlib._bootstrap>", line 1147, in _find_and_load_unlocked
  File "<frozen importlib._bootstrap>", line 690, in _load_unlocked
  File "<frozen importlib._bootstrap_external>", line 940, in exec_module
  File "<frozen importlib._bootstrap>", line 241, in _call_with_frames_removed
  File "C:\Users\91853\OneDrive\Desktop\tasks\aibee_social\aibee_social\urls.py", line 23, in <module>
    path('api/business/',include ('business.urls')),
                         ^^^^^^^^^^^^^^^^^^^^^^^^^
  File "C:\Users\91853\OneDrive\Desktop\tasks\aibee_social\env\Lib\site-packages\django\urls\conf.py", line 39, in include
    urlconf_module = import_module(urlconf_module)
                     ^^^^^^^^^^^^^^^^^^^^^^^^^^^^^
  File "C:\Users\91853\AppData\Local\Programs\Python\Python311\Lib\importlib\__init__.py", line 126, in import_module
    return _bootstrap._gcd_import(name[level:], package, level)
           ^^^^^^^^^^^^^^^^^^^^^^^^^^^^^^^^^^^^^^^^^^^^^^^^^^^^
  File "<frozen importlib._bootstrap>", line 1204, in _gcd_import
  File "<frozen importlib._bootstrap>", line 1176, in _find_and_load
  File "<frozen importlib._bootstrap>", line 1147, in _find_and_load_unlocked
  File "<frozen importlib._bootstrap>", line 690, in _load_unlocked
  File "<frozen importlib._bootstrap_external>", line 940, in exec_module
  File "<frozen importlib._bootstrap>", line 241, in _call_with_frames_removed
  File "C:\Users\91853\OneDrive\Desktop\tasks\aibee_social\business\urls.py", line 12, in <module>
    path('business-details/<int:id>/', BusinessDetailsRetrieveUpdate.as_view(), name='business-details-retrieve-update'),
                                       ^^^^^^^^^^^^^^^^^^^^^^^^^^^^^
NameError: name 'BusinessDetailsRetrieveUpdate' is not defined
C:\Users\91853\OneDrive\Desktop\tasks\aibee_social\business\urls.py changed, reloading.
DB_NAME socialdb
Performing system checks...

Watching for file changes with StatReloader
C:\Users\91853\OneDrive\Desktop\tasks\aibee_social\business\views.py changed, reloading.
DB_NAME socialdb
Performing system checks...

System check identified no issues (0 silenced).
February 19, 2025 - 17:14:14
Django version 5.1.6, using settings 'aibee_social.settings'
Starting development server at http://0.0.0.0:8000/
Quit the server with CTRL-BREAK.

Watching for file changes with StatReloader
C:\Users\91853\OneDrive\Desktop\tasks\aibee_social\business\views.py changed, reloading.
DB_NAME socialdb
Performing system checks...

System check identified no issues (0 silenced).
February 19, 2025 - 17:18:40
Django version 5.1.6, using settings 'aibee_social.settings'
Starting development server at http://0.0.0.0:8000/
Quit the server with CTRL-BREAK.

Watching for file changes with StatReloader
C:\Users\91853\OneDrive\Desktop\tasks\aibee_social\business\views.py changed, reloading.
DB_NAME socialdb
Performing system checks...

System check identified no issues (0 silenced).
February 19, 2025 - 17:20:45
Django version 5.1.6, using settings 'aibee_social.settings'
Starting development server at http://0.0.0.0:8000/
Quit the server with CTRL-BREAK.

Watching for file changes with StatReloader
C:\Users\91853\OneDrive\Desktop\tasks\aibee_social\business\views.py changed, reloading.
DB_NAME socialdb
Performing system checks...

System check identified no issues (0 silenced).
February 19, 2025 - 17:21:00
Django version 5.1.6, using settings 'aibee_social.settings'
Starting development server at http://0.0.0.0:8000/
Quit the server with CTRL-BREAK.

Watching for file changes with StatReloader
C:\Users\91853\OneDrive\Desktop\tasks\aibee_social\business\views.py changed, reloading.
DB_NAME socialdb
Performing system checks...

System check identified no issues (0 silenced).
February 19, 2025 - 17:21:14
Django version 5.1.6, using settings 'aibee_social.settings'
Starting development server at http://0.0.0.0:8000/
Quit the server with CTRL-BREAK.

Watching for file changes with StatReloader
C:\Users\91853\OneDrive\Desktop\tasks\aibee_social\business\views.py changed, reloading.
DB_NAME socialdb
Performing system checks...

System check identified no issues (0 silenced).
February 19, 2025 - 17:22:22
Django version 5.1.6, using settings 'aibee_social.settings'
Starting development server at http://0.0.0.0:8000/
Quit the server with CTRL-BREAK.

Watching for file changes with StatReloader
C:\Users\91853\OneDrive\Desktop\tasks\aibee_social\business\views.py changed, reloading.
DB_NAME socialdb
Performing system checks...

System check identified no issues (0 silenced).
February 19, 2025 - 17:23:33
Django version 5.1.6, using settings 'aibee_social.settings'
Starting development server at http://0.0.0.0:8000/
Quit the server with CTRL-BREAK.

Watching for file changes with StatReloader
C:\Users\91853\OneDrive\Desktop\tasks\aibee_social\business\views.py changed, reloading.
DB_NAME socialdb
Performing system checks...

System check identified no issues (0 silenced).
February 19, 2025 - 17:24:18
Django version 5.1.6, using settings 'aibee_social.settings'
Starting development server at http://0.0.0.0:8000/
Quit the server with CTRL-BREAK.

Watching for file changes with StatReloader
C:\Users\91853\OneDrive\Desktop\tasks\aibee_social\business\views.py changed, reloading.
DB_NAME socialdb
Performing system checks...

System check identified no issues (0 silenced).
February 19, 2025 - 17:24:22
Django version 5.1.6, using settings 'aibee_social.settings'
Starting development server at http://0.0.0.0:8000/
Quit the server with CTRL-BREAK.

Watching for file changes with StatReloader
C:\Users\91853\OneDrive\Desktop\tasks\aibee_social\business\views.py changed, reloading.
DB_NAME socialdb
Performing system checks...

System check identified no issues (0 silenced).
February 19, 2025 - 17:25:07
Django version 5.1.6, using settings 'aibee_social.settings'
Starting development server at http://0.0.0.0:8000/
Quit the server with CTRL-BREAK.

Watching for file changes with StatReloader
C:\Users\91853\OneDrive\Desktop\tasks\aibee_social\business\views.py changed, reloading.
DB_NAME socialdb
Performing system checks...

System check identified no issues (0 silenced).
February 19, 2025 - 17:26:09
Django version 5.1.6, using settings 'aibee_social.settings'
Starting development server at http://0.0.0.0:8000/
Quit the server with CTRL-BREAK.

Watching for file changes with StatReloader
C:\Users\91853\OneDrive\Desktop\tasks\aibee_social\business\views.py changed, reloading.
DB_NAME socialdb
Performing system checks...

System check identified no issues (0 silenced).
February 19, 2025 - 17:27:11
Django version 5.1.6, using settings 'aibee_social.settings'
Starting development server at http://0.0.0.0:8000/
Quit the server with CTRL-BREAK.

Watching for file changes with StatReloader
C:\Users\91853\OneDrive\Desktop\tasks\aibee_social\business\views.py changed, reloading.
DB_NAME socialdb
Performing system checks...

System check identified no issues (0 silenced).
February 19, 2025 - 17:32:56
Django version 5.1.6, using settings 'aibee_social.settings'
Starting development server at http://0.0.0.0:8000/
Quit the server with CTRL-BREAK.

Watching for file changes with StatReloader
C:\Users\91853\OneDrive\Desktop\tasks\aibee_social\business\views.py changed, reloading.
DB_NAME socialdb
Performing system checks...

System check identified no issues (0 silenced).
February 19, 2025 - 17:34:31
Django version 5.1.6, using settings 'aibee_social.settings'
Starting development server at http://0.0.0.0:8000/
Quit the server with CTRL-BREAK.

Watching for file changes with StatReloader
C:\Users\91853\OneDrive\Desktop\tasks\aibee_social\business\views.py changed, reloading.
DB_NAME socialdb
Performing system checks...

System check identified no issues (0 silenced).
February 19, 2025 - 17:34:55
Django version 5.1.6, using settings 'aibee_social.settings'
Starting development server at http://0.0.0.0:8000/
Quit the server with CTRL-BREAK.

Watching for file changes with StatReloader
C:\Users\91853\OneDrive\Desktop\tasks\aibee_social\business\views.py changed, reloading.
DB_NAME socialdb
Performing system checks...

System check identified no issues (0 silenced).
February 19, 2025 - 17:35:40
Django version 5.1.6, using settings 'aibee_social.settings'
Starting development server at http://0.0.0.0:8000/
Quit the server with CTRL-BREAK.

Watching for file changes with StatReloader
C:\Users\91853\OneDrive\Desktop\tasks\aibee_social\business\views.py changed, reloading.
DB_NAME socialdb
Performing system checks...

System check identified no issues (0 silenced).
February 19, 2025 - 17:36:10
Django version 5.1.6, using settings 'aibee_social.settings'
Starting development server at http://0.0.0.0:8000/
Quit the server with CTRL-BREAK.

Watching for file changes with StatReloader
C:\Users\91853\OneDrive\Desktop\tasks\aibee_social\business\views.py changed, reloading.
DB_NAME socialdb
Performing system checks...

System check identified no issues (0 silenced).
February 19, 2025 - 17:37:01
Django version 5.1.6, using settings 'aibee_social.settings'
Starting development server at http://0.0.0.0:8000/
Quit the server with CTRL-BREAK.

Watching for file changes with StatReloader
C:\Users\91853\OneDrive\Desktop\tasks\aibee_social\business\views.py changed, reloading.
DB_NAME socialdb
Performing system checks...

System check identified no issues (0 silenced).
February 19, 2025 - 17:37:27
Django version 5.1.6, using settings 'aibee_social.settings'
Starting development server at http://0.0.0.0:8000/
Quit the server with CTRL-BREAK.

Watching for file changes with StatReloader
C:\Users\91853\OneDrive\Desktop\tasks\aibee_social\business\urls.py changed, reloading.
DB_NAME socialdb
Performing system checks...

System check identified no issues (0 silenced).
February 19, 2025 - 17:37:54
Django version 5.1.6, using settings 'aibee_social.settings'
Starting development server at http://0.0.0.0:8000/
Quit the server with CTRL-BREAK.

Watching for file changes with StatReloader
C:\Users\91853\OneDrive\Desktop\tasks\aibee_social\business\urls.py changed, reloading.
DB_NAME socialdb
Performing system checks...

System check identified no issues (0 silenced).
February 19, 2025 - 17:39:31
Django version 5.1.6, using settings 'aibee_social.settings'
Starting development server at http://0.0.0.0:8000/
Quit the server with CTRL-BREAK.

Watching for file changes with StatReloader
Exception in thread django-main-thread:
Traceback (most recent call last):
  File "C:\Users\91853\AppData\Local\Programs\Python\Python311\Lib\threading.py", line 1038, in _bootstrap_inner
    self.run()
  File "C:\Users\91853\AppData\Local\Programs\Python\Python311\Lib\threading.py", line 975, in run
    self._target(*self._args, **self._kwargs)
  File "C:\Users\91853\OneDrive\Desktop\tasks\aibee_social\env\Lib\site-packages\django\utils\autoreload.py", line 64, in wrapper
    fn(*args, **kwargs)
  File "C:\Users\91853\OneDrive\Desktop\tasks\aibee_social\env\Lib\site-packages\django\core\management\commands\runserver.py", line 134, in inner_run
    self.check(display_num_errors=True)
  File "C:\Users\91853\OneDrive\Desktop\tasks\aibee_social\env\Lib\site-packages\django\core\management\base.py", line 486, in check
    all_issues = checks.run_checks(
                 ^^^^^^^^^^^^^^^^^^
  File "C:\Users\91853\OneDrive\Desktop\tasks\aibee_social\env\Lib\site-packages\django\core\checks\registry.py", line 88, in run_checks
    new_errors = check(app_configs=app_configs, databases=databases)
                 ^^^^^^^^^^^^^^^^^^^^^^^^^^^^^^^^^^^^^^^^^^^^^^^^^^^
  File "C:\Users\91853\OneDrive\Desktop\tasks\aibee_social\env\Lib\site-packages\django\core\checks\urls.py", line 136, in check_custom_error_handlers
    handler = resolver.resolve_error_handler(status_code)
              ^^^^^^^^^^^^^^^^^^^^^^^^^^^^^^^^^^^^^^^^^^^
  File "C:\Users\91853\OneDrive\Desktop\tasks\aibee_social\env\Lib\site-packages\django\urls\resolvers.py", line 732, in resolve_error_handler
    callback = getattr(self.urlconf_module, "handler%s" % view_type, None)
                       ^^^^^^^^^^^^^^^^^^^
  File "C:\Users\91853\OneDrive\Desktop\tasks\aibee_social\env\Lib\site-packages\django\utils\functional.py", line 47, in __get__
    res = instance.__dict__[self.name] = self.func(instance)
                                         ^^^^^^^^^^^^^^^^^^^
  File "C:\Users\91853\OneDrive\Desktop\tasks\aibee_social\env\Lib\site-packages\django\urls\resolvers.py", line 711, in urlconf_module
    return import_module(self.urlconf_name)
           ^^^^^^^^^^^^^^^^^^^^^^^^^^^^^^^^
  File "C:\Users\91853\AppData\Local\Programs\Python\Python311\Lib\importlib\__init__.py", line 126, in import_module
    return _bootstrap._gcd_import(name[level:], package, level)
           ^^^^^^^^^^^^^^^^^^^^^^^^^^^^^^^^^^^^^^^^^^^^^^^^^^^^
  File "<frozen importlib._bootstrap>", line 1204, in _gcd_import
  File "<frozen importlib._bootstrap>", line 1176, in _find_and_load
  File "<frozen importlib._bootstrap>", line 1147, in _find_and_load_unlocked
  File "<frozen importlib._bootstrap>", line 690, in _load_unlocked
  File "<frozen importlib._bootstrap_external>", line 940, in exec_module
  File "<frozen importlib._bootstrap>", line 241, in _call_with_frames_removed
  File "C:\Users\91853\OneDrive\Desktop\tasks\aibee_social\aibee_social\urls.py", line 23, in <module>
    path('api/business/',include ('business.urls')),
                         ^^^^^^^^^^^^^^^^^^^^^^^^^
  File "C:\Users\91853\OneDrive\Desktop\tasks\aibee_social\env\Lib\site-packages\django\urls\conf.py", line 39, in include
    urlconf_module = import_module(urlconf_module)
                     ^^^^^^^^^^^^^^^^^^^^^^^^^^^^^
  File "C:\Users\91853\AppData\Local\Programs\Python\Python311\Lib\importlib\__init__.py", line 126, in import_module
    return _bootstrap._gcd_import(name[level:], package, level)
           ^^^^^^^^^^^^^^^^^^^^^^^^^^^^^^^^^^^^^^^^^^^^^^^^^^^^
  File "<frozen importlib._bootstrap>", line 1204, in _gcd_import
  File "<frozen importlib._bootstrap>", line 1176, in _find_and_load
  File "<frozen importlib._bootstrap>", line 1147, in _find_and_load_unlocked
  File "<frozen importlib._bootstrap>", line 690, in _load_unlocked
  File "<frozen importlib._bootstrap_external>", line 940, in exec_module
  File "<frozen importlib._bootstrap>", line 241, in _call_with_frames_removed
  File "C:\Users\91853\OneDrive\Desktop\tasks\aibee_social\business\urls.py", line 13, in <module>
    path('business_profile_questionnaire/<int:pk>/', BusinessProfileQuestionnaireView.as_view(), name='business_profile_questionnaire_detail'), # Use pk
                                                     ^^^^^^^^^^^^^^^^^^^^^^^^^^^^^^^^
NameError: name 'BusinessProfileQuestionnaireView' is not defined. Did you mean: 'BusinessProfileQuestionnaire'?
C:\Users\91853\OneDrive\Desktop\tasks\aibee_social\business\urls.py changed, reloading.
DB_NAME socialdb
Performing system checks...

Watching for file changes with StatReloader
Exception in thread django-main-thread:
Traceback (most recent call last):
  File "C:\Users\91853\AppData\Local\Programs\Python\Python311\Lib\threading.py", line 1038, in _bootstrap_inner
    self.run()
  File "C:\Users\91853\AppData\Local\Programs\Python\Python311\Lib\threading.py", line 975, in run
    self._target(*self._args, **self._kwargs)
  File "C:\Users\91853\OneDrive\Desktop\tasks\aibee_social\env\Lib\site-packages\django\utils\autoreload.py", line 64, in wrapper
    fn(*args, **kwargs)
  File "C:\Users\91853\OneDrive\Desktop\tasks\aibee_social\env\Lib\site-packages\django\core\management\commands\runserver.py", line 134, in inner_run
    self.check(display_num_errors=True)
  File "C:\Users\91853\OneDrive\Desktop\tasks\aibee_social\env\Lib\site-packages\django\core\management\base.py", line 486, in check
    all_issues = checks.run_checks(
                 ^^^^^^^^^^^^^^^^^^
  File "C:\Users\91853\OneDrive\Desktop\tasks\aibee_social\env\Lib\site-packages\django\core\checks\registry.py", line 88, in run_checks
    new_errors = check(app_configs=app_configs, databases=databases)
                 ^^^^^^^^^^^^^^^^^^^^^^^^^^^^^^^^^^^^^^^^^^^^^^^^^^^
  File "C:\Users\91853\OneDrive\Desktop\tasks\aibee_social\env\Lib\site-packages\django\core\checks\urls.py", line 136, in check_custom_error_handlers
    handler = resolver.resolve_error_handler(status_code)
              ^^^^^^^^^^^^^^^^^^^^^^^^^^^^^^^^^^^^^^^^^^^
  File "C:\Users\91853\OneDrive\Desktop\tasks\aibee_social\env\Lib\site-packages\django\urls\resolvers.py", line 732, in resolve_error_handler
    callback = getattr(self.urlconf_module, "handler%s" % view_type, None)
                       ^^^^^^^^^^^^^^^^^^^
  File "C:\Users\91853\OneDrive\Desktop\tasks\aibee_social\env\Lib\site-packages\django\utils\functional.py", line 47, in __get__
    res = instance.__dict__[self.name] = self.func(instance)
                                         ^^^^^^^^^^^^^^^^^^^
  File "C:\Users\91853\OneDrive\Desktop\tasks\aibee_social\env\Lib\site-packages\django\urls\resolvers.py", line 711, in urlconf_module
    return import_module(self.urlconf_name)
           ^^^^^^^^^^^^^^^^^^^^^^^^^^^^^^^^
  File "C:\Users\91853\AppData\Local\Programs\Python\Python311\Lib\importlib\__init__.py", line 126, in import_module
    return _bootstrap._gcd_import(name[level:], package, level)
           ^^^^^^^^^^^^^^^^^^^^^^^^^^^^^^^^^^^^^^^^^^^^^^^^^^^^
  File "<frozen importlib._bootstrap>", line 1204, in _gcd_import
  File "<frozen importlib._bootstrap>", line 1176, in _find_and_load
  File "<frozen importlib._bootstrap>", line 1147, in _find_and_load_unlocked
  File "<frozen importlib._bootstrap>", line 690, in _load_unlocked
  File "<frozen importlib._bootstrap_external>", line 940, in exec_module
  File "<frozen importlib._bootstrap>", line 241, in _call_with_frames_removed
  File "C:\Users\91853\OneDrive\Desktop\tasks\aibee_social\aibee_social\urls.py", line 23, in <module>
    path('api/business/',include ('business.urls')),
                         ^^^^^^^^^^^^^^^^^^^^^^^^^
  File "C:\Users\91853\OneDrive\Desktop\tasks\aibee_social\env\Lib\site-packages\django\urls\conf.py", line 39, in include
    urlconf_module = import_module(urlconf_module)
                     ^^^^^^^^^^^^^^^^^^^^^^^^^^^^^
  File "C:\Users\91853\AppData\Local\Programs\Python\Python311\Lib\importlib\__init__.py", line 126, in import_module
    return _bootstrap._gcd_import(name[level:], package, level)
           ^^^^^^^^^^^^^^^^^^^^^^^^^^^^^^^^^^^^^^^^^^^^^^^^^^^^
  File "<frozen importlib._bootstrap>", line 1204, in _gcd_import
  File "<frozen importlib._bootstrap>", line 1176, in _find_and_load
  File "<frozen importlib._bootstrap>", line 1147, in _find_and_load_unlocked
  File "<frozen importlib._bootstrap>", line 690, in _load_unlocked
  File "<frozen importlib._bootstrap_external>", line 940, in exec_module
  File "<frozen importlib._bootstrap>", line 241, in _call_with_frames_removed
  File "C:\Users\91853\OneDrive\Desktop\tasks\aibee_social\business\urls.py", line 13, in <module>
    path('business_profile_questionnaire/<int:pk>/', BusinessProfileQuestionnaireView.as_view(), name='business_profile_questionnaire_detail'), # Use pk
                                                     ^^^^^^^^^^^^^^^^^^^^^^^^^^^^^^^^
NameError: name 'BusinessProfileQuestionnaireView' is not defined. Did you mean: 'BusinessProfileQuestionnaire'?
C:\Users\91853\OneDrive\Desktop\tasks\aibee_social\business\urls.py changed, reloading.
DB_NAME socialdb
Performing system checks...

Watching for file changes with StatReloader
Exception in thread django-main-thread:
Traceback (most recent call last):
  File "C:\Users\91853\AppData\Local\Programs\Python\Python311\Lib\threading.py", line 1038, in _bootstrap_inner
    self.run()
  File "C:\Users\91853\AppData\Local\Programs\Python\Python311\Lib\threading.py", line 975, in run
    self._target(*self._args, **self._kwargs)
  File "C:\Users\91853\OneDrive\Desktop\tasks\aibee_social\env\Lib\site-packages\django\utils\autoreload.py", line 64, in wrapper
    fn(*args, **kwargs)
  File "C:\Users\91853\OneDrive\Desktop\tasks\aibee_social\env\Lib\site-packages\django\core\management\commands\runserver.py", line 134, in inner_run
    self.check(display_num_errors=True)
  File "C:\Users\91853\OneDrive\Desktop\tasks\aibee_social\env\Lib\site-packages\django\core\management\base.py", line 486, in check
    all_issues = checks.run_checks(
                 ^^^^^^^^^^^^^^^^^^
  File "C:\Users\91853\OneDrive\Desktop\tasks\aibee_social\env\Lib\site-packages\django\core\checks\registry.py", line 88, in run_checks
    new_errors = check(app_configs=app_configs, databases=databases)
                 ^^^^^^^^^^^^^^^^^^^^^^^^^^^^^^^^^^^^^^^^^^^^^^^^^^^
  File "C:\Users\91853\OneDrive\Desktop\tasks\aibee_social\env\Lib\site-packages\django\core\checks\urls.py", line 136, in check_custom_error_handlers
    handler = resolver.resolve_error_handler(status_code)
              ^^^^^^^^^^^^^^^^^^^^^^^^^^^^^^^^^^^^^^^^^^^
  File "C:\Users\91853\OneDrive\Desktop\tasks\aibee_social\env\Lib\site-packages\django\urls\resolvers.py", line 732, in resolve_error_handler
    callback = getattr(self.urlconf_module, "handler%s" % view_type, None)
                       ^^^^^^^^^^^^^^^^^^^
  File "C:\Users\91853\OneDrive\Desktop\tasks\aibee_social\env\Lib\site-packages\django\utils\functional.py", line 47, in __get__
    res = instance.__dict__[self.name] = self.func(instance)
                                         ^^^^^^^^^^^^^^^^^^^
  File "C:\Users\91853\OneDrive\Desktop\tasks\aibee_social\env\Lib\site-packages\django\urls\resolvers.py", line 711, in urlconf_module
    return import_module(self.urlconf_name)
           ^^^^^^^^^^^^^^^^^^^^^^^^^^^^^^^^
  File "C:\Users\91853\AppData\Local\Programs\Python\Python311\Lib\importlib\__init__.py", line 126, in import_module
    return _bootstrap._gcd_import(name[level:], package, level)
           ^^^^^^^^^^^^^^^^^^^^^^^^^^^^^^^^^^^^^^^^^^^^^^^^^^^^
  File "<frozen importlib._bootstrap>", line 1204, in _gcd_import
  File "<frozen importlib._bootstrap>", line 1176, in _find_and_load
  File "<frozen importlib._bootstrap>", line 1147, in _find_and_load_unlocked
  File "<frozen importlib._bootstrap>", line 690, in _load_unlocked
  File "<frozen importlib._bootstrap_external>", line 940, in exec_module
  File "<frozen importlib._bootstrap>", line 241, in _call_with_frames_removed
  File "C:\Users\91853\OneDrive\Desktop\tasks\aibee_social\aibee_social\urls.py", line 23, in <module>
    path('api/business/',include ('business.urls')),
                         ^^^^^^^^^^^^^^^^^^^^^^^^^
  File "C:\Users\91853\OneDrive\Desktop\tasks\aibee_social\env\Lib\site-packages\django\urls\conf.py", line 39, in include
    urlconf_module = import_module(urlconf_module)
                     ^^^^^^^^^^^^^^^^^^^^^^^^^^^^^
  File "C:\Users\91853\AppData\Local\Programs\Python\Python311\Lib\importlib\__init__.py", line 126, in import_module
    return _bootstrap._gcd_import(name[level:], package, level)
           ^^^^^^^^^^^^^^^^^^^^^^^^^^^^^^^^^^^^^^^^^^^^^^^^^^^^
  File "<frozen importlib._bootstrap>", line 1204, in _gcd_import
  File "<frozen importlib._bootstrap>", line 1176, in _find_and_load
  File "<frozen importlib._bootstrap>", line 1147, in _find_and_load_unlocked
  File "<frozen importlib._bootstrap>", line 690, in _load_unlocked
  File "<frozen importlib._bootstrap_external>", line 940, in exec_module
  File "<frozen importlib._bootstrap>", line 241, in _call_with_frames_removed
  File "C:\Users\91853\OneDrive\Desktop\tasks\aibee_social\business\urls.py", line 13, in <module>
    path('business_profile_questionnaire/<int:pk>/', BusinessProfileQuestionnaireView.as_view(), name='business_profile_questionnaire_detail'), # Use pk
                                                     ^^^^^^^^^^^^^^^^^^^^^^^^^^^^^^^^
NameError: name 'BusinessProfileQuestionnaireView' is not defined. Did you mean: 'BusinessProfileQuestionnaire'?
C:\Users\91853\OneDrive\Desktop\tasks\aibee_social\business\urls.py changed, reloading.
DB_NAME socialdb
Performing system checks...

Watching for file changes with StatReloader
Exception in thread django-main-thread:
Traceback (most recent call last):
  File "C:\Users\91853\AppData\Local\Programs\Python\Python311\Lib\threading.py", line 1038, in _bootstrap_inner
    self.run()
  File "C:\Users\91853\AppData\Local\Programs\Python\Python311\Lib\threading.py", line 975, in run
    self._target(*self._args, **self._kwargs)
  File "C:\Users\91853\OneDrive\Desktop\tasks\aibee_social\env\Lib\site-packages\django\utils\autoreload.py", line 64, in wrapper
    fn(*args, **kwargs)
  File "C:\Users\91853\OneDrive\Desktop\tasks\aibee_social\env\Lib\site-packages\django\core\management\commands\runserver.py", line 134, in inner_run
    self.check(display_num_errors=True)
  File "C:\Users\91853\OneDrive\Desktop\tasks\aibee_social\env\Lib\site-packages\django\core\management\base.py", line 486, in check
    all_issues = checks.run_checks(
                 ^^^^^^^^^^^^^^^^^^
  File "C:\Users\91853\OneDrive\Desktop\tasks\aibee_social\env\Lib\site-packages\django\core\checks\registry.py", line 88, in run_checks
    new_errors = check(app_configs=app_configs, databases=databases)
                 ^^^^^^^^^^^^^^^^^^^^^^^^^^^^^^^^^^^^^^^^^^^^^^^^^^^
  File "C:\Users\91853\OneDrive\Desktop\tasks\aibee_social\env\Lib\site-packages\django\core\checks\urls.py", line 136, in check_custom_error_handlers
    handler = resolver.resolve_error_handler(status_code)
              ^^^^^^^^^^^^^^^^^^^^^^^^^^^^^^^^^^^^^^^^^^^
  File "C:\Users\91853\OneDrive\Desktop\tasks\aibee_social\env\Lib\site-packages\django\urls\resolvers.py", line 732, in resolve_error_handler
    callback = getattr(self.urlconf_module, "handler%s" % view_type, None)
                       ^^^^^^^^^^^^^^^^^^^
  File "C:\Users\91853\OneDrive\Desktop\tasks\aibee_social\env\Lib\site-packages\django\utils\functional.py", line 47, in __get__
    res = instance.__dict__[self.name] = self.func(instance)
                                         ^^^^^^^^^^^^^^^^^^^
  File "C:\Users\91853\OneDrive\Desktop\tasks\aibee_social\env\Lib\site-packages\django\urls\resolvers.py", line 711, in urlconf_module
    return import_module(self.urlconf_name)
           ^^^^^^^^^^^^^^^^^^^^^^^^^^^^^^^^
  File "C:\Users\91853\AppData\Local\Programs\Python\Python311\Lib\importlib\__init__.py", line 126, in import_module
    return _bootstrap._gcd_import(name[level:], package, level)
           ^^^^^^^^^^^^^^^^^^^^^^^^^^^^^^^^^^^^^^^^^^^^^^^^^^^^
  File "<frozen importlib._bootstrap>", line 1204, in _gcd_import
  File "<frozen importlib._bootstrap>", line 1176, in _find_and_load
  File "<frozen importlib._bootstrap>", line 1147, in _find_and_load_unlocked
  File "<frozen importlib._bootstrap>", line 690, in _load_unlocked
  File "<frozen importlib._bootstrap_external>", line 940, in exec_module
  File "<frozen importlib._bootstrap>", line 241, in _call_with_frames_removed
  File "C:\Users\91853\OneDrive\Desktop\tasks\aibee_social\aibee_social\urls.py", line 23, in <module>
    path('api/business/',include ('business.urls')),
                         ^^^^^^^^^^^^^^^^^^^^^^^^^
  File "C:\Users\91853\OneDrive\Desktop\tasks\aibee_social\env\Lib\site-packages\django\urls\conf.py", line 39, in include
    urlconf_module = import_module(urlconf_module)
                     ^^^^^^^^^^^^^^^^^^^^^^^^^^^^^
  File "C:\Users\91853\AppData\Local\Programs\Python\Python311\Lib\importlib\__init__.py", line 126, in import_module
    return _bootstrap._gcd_import(name[level:], package, level)
           ^^^^^^^^^^^^^^^^^^^^^^^^^^^^^^^^^^^^^^^^^^^^^^^^^^^^
  File "<frozen importlib._bootstrap>", line 1204, in _gcd_import
  File "<frozen importlib._bootstrap>", line 1176, in _find_and_load
  File "<frozen importlib._bootstrap>", line 1147, in _find_and_load_unlocked
  File "<frozen importlib._bootstrap>", line 690, in _load_unlocked
  File "<frozen importlib._bootstrap_external>", line 940, in exec_module
  File "<frozen importlib._bootstrap>", line 241, in _call_with_frames_removed
  File "C:\Users\91853\OneDrive\Desktop\tasks\aibee_social\business\urls.py", line 13, in <module>
    path('business_profile_questionnaire/<int:pk>/', BusinessProfileQuestionnaireView.as_view(), name='business_profile_questionnaire_detail'), # Use pk
                                                     ^^^^^^^^^^^^^^^^^^^^^^^^^^^^^^^^
NameError: name 'BusinessProfileQuestionnaireView' is not defined. Did you mean: 'BusinessProfileQuestionnaire'?
C:\Users\91853\OneDrive\Desktop\tasks\aibee_social\business\urls.py changed, reloading.
DB_NAME socialdb
Performing system checks...

Watching for file changes with StatReloader
Exception in thread django-main-thread:
Traceback (most recent call last):
  File "C:\Users\91853\AppData\Local\Programs\Python\Python311\Lib\threading.py", line 1038, in _bootstrap_inner
    self.run()
  File "C:\Users\91853\AppData\Local\Programs\Python\Python311\Lib\threading.py", line 975, in run
    self._target(*self._args, **self._kwargs)
  File "C:\Users\91853\OneDrive\Desktop\tasks\aibee_social\env\Lib\site-packages\django\utils\autoreload.py", line 64, in wrapper
    fn(*args, **kwargs)
  File "C:\Users\91853\OneDrive\Desktop\tasks\aibee_social\env\Lib\site-packages\django\core\management\commands\runserver.py", line 134, in inner_run
    self.check(display_num_errors=True)
  File "C:\Users\91853\OneDrive\Desktop\tasks\aibee_social\env\Lib\site-packages\django\core\management\base.py", line 486, in check
    all_issues = checks.run_checks(
                 ^^^^^^^^^^^^^^^^^^
  File "C:\Users\91853\OneDrive\Desktop\tasks\aibee_social\env\Lib\site-packages\django\core\checks\registry.py", line 88, in run_checks
    new_errors = check(app_configs=app_configs, databases=databases)
                 ^^^^^^^^^^^^^^^^^^^^^^^^^^^^^^^^^^^^^^^^^^^^^^^^^^^
  File "C:\Users\91853\OneDrive\Desktop\tasks\aibee_social\env\Lib\site-packages\django\core\checks\urls.py", line 136, in check_custom_error_handlers
    handler = resolver.resolve_error_handler(status_code)
              ^^^^^^^^^^^^^^^^^^^^^^^^^^^^^^^^^^^^^^^^^^^
  File "C:\Users\91853\OneDrive\Desktop\tasks\aibee_social\env\Lib\site-packages\django\urls\resolvers.py", line 732, in resolve_error_handler
    callback = getattr(self.urlconf_module, "handler%s" % view_type, None)
                       ^^^^^^^^^^^^^^^^^^^
  File "C:\Users\91853\OneDrive\Desktop\tasks\aibee_social\env\Lib\site-packages\django\utils\functional.py", line 47, in __get__
    res = instance.__dict__[self.name] = self.func(instance)
                                         ^^^^^^^^^^^^^^^^^^^
  File "C:\Users\91853\OneDrive\Desktop\tasks\aibee_social\env\Lib\site-packages\django\urls\resolvers.py", line 711, in urlconf_module
    return import_module(self.urlconf_name)
           ^^^^^^^^^^^^^^^^^^^^^^^^^^^^^^^^
  File "C:\Users\91853\AppData\Local\Programs\Python\Python311\Lib\importlib\__init__.py", line 126, in import_module
    return _bootstrap._gcd_import(name[level:], package, level)
           ^^^^^^^^^^^^^^^^^^^^^^^^^^^^^^^^^^^^^^^^^^^^^^^^^^^^
  File "<frozen importlib._bootstrap>", line 1204, in _gcd_import
  File "<frozen importlib._bootstrap>", line 1176, in _find_and_load
  File "<frozen importlib._bootstrap>", line 1147, in _find_and_load_unlocked
  File "<frozen importlib._bootstrap>", line 690, in _load_unlocked
  File "<frozen importlib._bootstrap_external>", line 940, in exec_module
  File "<frozen importlib._bootstrap>", line 241, in _call_with_frames_removed
  File "C:\Users\91853\OneDrive\Desktop\tasks\aibee_social\aibee_social\urls.py", line 23, in <module>
    path('api/business/',include ('business.urls')),
                         ^^^^^^^^^^^^^^^^^^^^^^^^^
  File "C:\Users\91853\OneDrive\Desktop\tasks\aibee_social\env\Lib\site-packages\django\urls\conf.py", line 39, in include
    urlconf_module = import_module(urlconf_module)
                     ^^^^^^^^^^^^^^^^^^^^^^^^^^^^^
  File "C:\Users\91853\AppData\Local\Programs\Python\Python311\Lib\importlib\__init__.py", line 126, in import_module
    return _bootstrap._gcd_import(name[level:], package, level)
           ^^^^^^^^^^^^^^^^^^^^^^^^^^^^^^^^^^^^^^^^^^^^^^^^^^^^
  File "<frozen importlib._bootstrap>", line 1204, in _gcd_import
  File "<frozen importlib._bootstrap>", line 1176, in _find_and_load
  File "<frozen importlib._bootstrap>", line 1147, in _find_and_load_unlocked
  File "<frozen importlib._bootstrap>", line 690, in _load_unlocked
  File "<frozen importlib._bootstrap_external>", line 940, in exec_module
  File "<frozen importlib._bootstrap>", line 241, in _call_with_frames_removed
  File "C:\Users\91853\OneDrive\Desktop\tasks\aibee_social\business\urls.py", line 13, in <module>
    path('business_profile_questionnaire/<int:pk>/', BusinessProfileQuestionnaireView.as_view(), name='business_profile_questionnaire_detail'), # Use pk
                                                     ^^^^^^^^^^^^^^^^^^^^^^^^^^^^^^^^
NameError: name 'BusinessProfileQuestionnaireView' is not defined. Did you mean: 'BusinessProfileQuestionnaire'?
C:\Users\91853\OneDrive\Desktop\tasks\aibee_social\business\urls.py changed, reloading.
DB_NAME socialdb
Performing system checks...

Watching for file changes with StatReloader
Exception in thread django-main-thread:
Traceback (most recent call last):
  File "C:\Users\91853\AppData\Local\Programs\Python\Python311\Lib\threading.py", line 1038, in _bootstrap_inner
    self.run()
  File "C:\Users\91853\AppData\Local\Programs\Python\Python311\Lib\threading.py", line 975, in run
    self._target(*self._args, **self._kwargs)
  File "C:\Users\91853\OneDrive\Desktop\tasks\aibee_social\env\Lib\site-packages\django\utils\autoreload.py", line 64, in wrapper
    fn(*args, **kwargs)
  File "C:\Users\91853\OneDrive\Desktop\tasks\aibee_social\env\Lib\site-packages\django\core\management\commands\runserver.py", line 134, in inner_run
    self.check(display_num_errors=True)
  File "C:\Users\91853\OneDrive\Desktop\tasks\aibee_social\env\Lib\site-packages\django\core\management\base.py", line 486, in check
    all_issues = checks.run_checks(
                 ^^^^^^^^^^^^^^^^^^
  File "C:\Users\91853\OneDrive\Desktop\tasks\aibee_social\env\Lib\site-packages\django\core\checks\registry.py", line 88, in run_checks
    new_errors = check(app_configs=app_configs, databases=databases)
                 ^^^^^^^^^^^^^^^^^^^^^^^^^^^^^^^^^^^^^^^^^^^^^^^^^^^
  File "C:\Users\91853\OneDrive\Desktop\tasks\aibee_social\env\Lib\site-packages\django\core\checks\urls.py", line 136, in check_custom_error_handlers
    handler = resolver.resolve_error_handler(status_code)
              ^^^^^^^^^^^^^^^^^^^^^^^^^^^^^^^^^^^^^^^^^^^
  File "C:\Users\91853\OneDrive\Desktop\tasks\aibee_social\env\Lib\site-packages\django\urls\resolvers.py", line 732, in resolve_error_handler
    callback = getattr(self.urlconf_module, "handler%s" % view_type, None)
                       ^^^^^^^^^^^^^^^^^^^
  File "C:\Users\91853\OneDrive\Desktop\tasks\aibee_social\env\Lib\site-packages\django\utils\functional.py", line 47, in __get__
    res = instance.__dict__[self.name] = self.func(instance)
                                         ^^^^^^^^^^^^^^^^^^^
  File "C:\Users\91853\OneDrive\Desktop\tasks\aibee_social\env\Lib\site-packages\django\urls\resolvers.py", line 711, in urlconf_module
    return import_module(self.urlconf_name)
           ^^^^^^^^^^^^^^^^^^^^^^^^^^^^^^^^
  File "C:\Users\91853\AppData\Local\Programs\Python\Python311\Lib\importlib\__init__.py", line 126, in import_module
    return _bootstrap._gcd_import(name[level:], package, level)
           ^^^^^^^^^^^^^^^^^^^^^^^^^^^^^^^^^^^^^^^^^^^^^^^^^^^^
  File "<frozen importlib._bootstrap>", line 1204, in _gcd_import
  File "<frozen importlib._bootstrap>", line 1176, in _find_and_load
  File "<frozen importlib._bootstrap>", line 1147, in _find_and_load_unlocked
  File "<frozen importlib._bootstrap>", line 690, in _load_unlocked
  File "<frozen importlib._bootstrap_external>", line 940, in exec_module
  File "<frozen importlib._bootstrap>", line 241, in _call_with_frames_removed
  File "C:\Users\91853\OneDrive\Desktop\tasks\aibee_social\aibee_social\urls.py", line 23, in <module>
    path('api/business/',include ('business.urls')),
                         ^^^^^^^^^^^^^^^^^^^^^^^^^
  File "C:\Users\91853\OneDrive\Desktop\tasks\aibee_social\env\Lib\site-packages\django\urls\conf.py", line 39, in include
    urlconf_module = import_module(urlconf_module)
                     ^^^^^^^^^^^^^^^^^^^^^^^^^^^^^
  File "C:\Users\91853\AppData\Local\Programs\Python\Python311\Lib\importlib\__init__.py", line 126, in import_module
    return _bootstrap._gcd_import(name[level:], package, level)
           ^^^^^^^^^^^^^^^^^^^^^^^^^^^^^^^^^^^^^^^^^^^^^^^^^^^^
  File "<frozen importlib._bootstrap>", line 1204, in _gcd_import
  File "<frozen importlib._bootstrap>", line 1176, in _find_and_load
  File "<frozen importlib._bootstrap>", line 1147, in _find_and_load_unlocked
  File "<frozen importlib._bootstrap>", line 690, in _load_unlocked
  File "<frozen importlib._bootstrap_external>", line 940, in exec_module
  File "<frozen importlib._bootstrap>", line 241, in _call_with_frames_removed
  File "C:\Users\91853\OneDrive\Desktop\tasks\aibee_social\business\urls.py", line 13, in <module>
    path('business_profile_questionnaire/<int:pk>/', BusinessProfileQuestionnaireView.as_view(), name='business_profile_questionnaire_detail'),
                                                     ^^^^^^^^^^^^^^^^^^^^^^^^^^^^^^^^
NameError: name 'BusinessProfileQuestionnaireView' is not defined. Did you mean: 'BusinessProfileQuestionnaire'?
C:\Users\91853\OneDrive\Desktop\tasks\aibee_social\business\urls.py changed, reloading.
DB_NAME socialdb
Performing system checks...

Watching for file changes with StatReloader
C:\Users\91853\OneDrive\Desktop\tasks\aibee_social\business\views.py changed, reloading.
DB_NAME socialdb
Performing system checks...

System check identified no issues (0 silenced).
February 19, 2025 - 17:42:42
Django version 5.1.6, using settings 'aibee_social.settings'
Starting development server at http://0.0.0.0:8000/
Quit the server with CTRL-BREAK.

Watching for file changes with StatReloader
C:\Users\91853\OneDrive\Desktop\tasks\aibee_social\business\views.py changed, reloading.
DB_NAME socialdb
Performing system checks...

System check identified no issues (0 silenced).
February 19, 2025 - 17:44:41
Django version 5.1.6, using settings 'aibee_social.settings'
Starting development server at http://0.0.0.0:8000/
Quit the server with CTRL-BREAK.

Watching for file changes with StatReloader
C:\Users\91853\OneDrive\Desktop\tasks\aibee_social\business\views.py changed, reloading.
DB_NAME socialdb
Performing system checks...

System check identified no issues (0 silenced).
February 19, 2025 - 17:47:31
Django version 5.1.6, using settings 'aibee_social.settings'
Starting development server at http://0.0.0.0:8000/
Quit the server with CTRL-BREAK.

Watching for file changes with StatReloader
C:\Users\91853\OneDrive\Desktop\tasks\aibee_social\business\models.py changed, reloading.
DB_NAME socialdb
Performing system checks...

System check identified no issues (0 silenced).
February 19, 2025 - 17:50:14
Django version 5.1.6, using settings 'aibee_social.settings'
Starting development server at http://0.0.0.0:8000/
Quit the server with CTRL-BREAK.

Watching for file changes with StatReloader
Exception in thread django-main-thread:
Traceback (most recent call last):
  File "C:\Users\91853\OneDrive\Desktop\tasks\aibee_social\env\Lib\site-packages\django\core\checks\urls.py", line 136, in check_custom_error_handlers
    handler = resolver.resolve_error_handler(status_code)
              ^^^^^^^^^^^^^^^^^^^^^^^^^^^^^^^^^^^^^^^^^^^
  File "C:\Users\91853\OneDrive\Desktop\tasks\aibee_social\env\Lib\site-packages\django\urls\resolvers.py", line 732, in resolve_error_handler
    callback = getattr(self.urlconf_module, "handler%s" % view_type, None)
                       ^^^^^^^^^^^^^^^^^^^
  File "C:\Users\91853\OneDrive\Desktop\tasks\aibee_social\env\Lib\site-packages\django\utils\functional.py", line 47, in __get__
    res = instance.__dict__[self.name] = self.func(instance)
                                         ^^^^^^^^^^^^^^^^^^^
  File "C:\Users\91853\OneDrive\Desktop\tasks\aibee_social\env\Lib\site-packages\django\urls\resolvers.py", line 711, in urlconf_module
    return import_module(self.urlconf_name)
           ^^^^^^^^^^^^^^^^^^^^^^^^^^^^^^^^
  File "C:\Users\91853\AppData\Local\Programs\Python\Python311\Lib\importlib\__init__.py", line 126, in import_module
    return _bootstrap._gcd_import(name[level:], package, level)
           ^^^^^^^^^^^^^^^^^^^^^^^^^^^^^^^^^^^^^^^^^^^^^^^^^^^^
  File "<frozen importlib._bootstrap>", line 1204, in _gcd_import
  File "<frozen importlib._bootstrap>", line 1176, in _find_and_load
  File "<frozen importlib._bootstrap>", line 1147, in _find_and_load_unlocked
  File "<frozen importlib._bootstrap>", line 690, in _load_unlocked
  File "<frozen importlib._bootstrap_external>", line 940, in exec_module
  File "<frozen importlib._bootstrap>", line 241, in _call_with_frames_removed
  File "C:\Users\91853\OneDrive\Desktop\tasks\aibee_social\aibee_social\urls.py", line 23, in <module>
    path('api/business/',include ('business.urls')),
                         ^^^^^^^^^^^^^^^^^^^^^^^^^
  File "C:\Users\91853\OneDrive\Desktop\tasks\aibee_social\env\Lib\site-packages\django\urls\conf.py", line 39, in include
    urlconf_module = import_module(urlconf_module)
                     ^^^^^^^^^^^^^^^^^^^^^^^^^^^^^
  File "C:\Users\91853\AppData\Local\Programs\Python\Python311\Lib\importlib\__init__.py", line 126, in import_module
    return _bootstrap._gcd_import(name[level:], package, level)
           ^^^^^^^^^^^^^^^^^^^^^^^^^^^^^^^^^^^^^^^^^^^^^^^^^^^^
  File "<frozen importlib._bootstrap>", line 1204, in _gcd_import
  File "<frozen importlib._bootstrap>", line 1176, in _find_and_load
  File "<frozen importlib._bootstrap>", line 1147, in _find_and_load_unlocked
  File "<frozen importlib._bootstrap>", line 690, in _load_unlocked
  File "<frozen importlib._bootstrap_external>", line 940, in exec_module
  File "<frozen importlib._bootstrap>", line 241, in _call_with_frames_removed
  File "C:\Users\91853\OneDrive\Desktop\tasks\aibee_social\business\urls.py", line 1, in <module>
    from business.views import (BusinessDetailsListCreate,BusinessProfileQuestionnaire,CommunicationPreferences,CommunicationStyle,
  File "C:\Users\91853\OneDrive\Desktop\tasks\aibee_social\business\views.py", line 2, in <module>
    from .serializers import (BusinessDetailsSerializer,BusinessProfileQuestionnaireSerializer,CommunicationPreferencesSerializer,
  File "C:\Users\91853\OneDrive\Desktop\tasks\aibee_social\business\serializers.py", line 3, in <module>
    from .models import (
ImportError: cannot import name 'contenttypes' from 'business.models' (C:\Users\91853\OneDrive\Desktop\tasks\aibee_social\business\models.py)

During handling of the above exception, another exception occurred:

Traceback (most recent call last):
  File "C:\Users\91853\AppData\Local\Programs\Python\Python311\Lib\threading.py", line 1038, in _bootstrap_inner
    self.run()
  File "C:\Users\91853\AppData\Local\Programs\Python\Python311\Lib\threading.py", line 975, in run
    self._target(*self._args, **self._kwargs)
  File "C:\Users\91853\OneDrive\Desktop\tasks\aibee_social\env\Lib\site-packages\django\utils\autoreload.py", line 64, in wrapper
    fn(*args, **kwargs)
  File "C:\Users\91853\OneDrive\Desktop\tasks\aibee_social\env\Lib\site-packages\django\core\management\commands\runserver.py", line 134, in inner_run
    self.check(display_num_errors=True)
  File "C:\Users\91853\OneDrive\Desktop\tasks\aibee_social\env\Lib\site-packages\django\core\management\base.py", line 486, in check
    all_issues = checks.run_checks(
                 ^^^^^^^^^^^^^^^^^^
  File "C:\Users\91853\OneDrive\Desktop\tasks\aibee_social\env\Lib\site-packages\django\core\checks\registry.py", line 88, in run_checks
    new_errors = check(app_configs=app_configs, databases=databases)
                 ^^^^^^^^^^^^^^^^^^^^^^^^^^^^^^^^^^^^^^^^^^^^^^^^^^^
  File "C:\Users\91853\OneDrive\Desktop\tasks\aibee_social\env\Lib\site-packages\django\core\checks\urls.py", line 138, in check_custom_error_handlers
    path = getattr(resolver.urlconf_module, "handler%s" % status_code)
                   ^^^^^^^^^^^^^^^^^^^^^^^
  File "C:\Users\91853\OneDrive\Desktop\tasks\aibee_social\env\Lib\site-packages\django\utils\functional.py", line 47, in __get__
    res = instance.__dict__[self.name] = self.func(instance)
                                         ^^^^^^^^^^^^^^^^^^^
  File "C:\Users\91853\OneDrive\Desktop\tasks\aibee_social\env\Lib\site-packages\django\urls\resolvers.py", line 711, in urlconf_module
    return import_module(self.urlconf_name)
           ^^^^^^^^^^^^^^^^^^^^^^^^^^^^^^^^
  File "C:\Users\91853\AppData\Local\Programs\Python\Python311\Lib\importlib\__init__.py", line 126, in import_module
    return _bootstrap._gcd_import(name[level:], package, level)
           ^^^^^^^^^^^^^^^^^^^^^^^^^^^^^^^^^^^^^^^^^^^^^^^^^^^^
  File "<frozen importlib._bootstrap>", line 1204, in _gcd_import
  File "<frozen importlib._bootstrap>", line 1176, in _find_and_load
  File "<frozen importlib._bootstrap>", line 1147, in _find_and_load_unlocked
  File "<frozen importlib._bootstrap>", line 690, in _load_unlocked
  File "<frozen importlib._bootstrap_external>", line 940, in exec_module
  File "<frozen importlib._bootstrap>", line 241, in _call_with_frames_removed
  File "C:\Users\91853\OneDrive\Desktop\tasks\aibee_social\aibee_social\urls.py", line 23, in <module>
    path('api/business/',include ('business.urls')),
                         ^^^^^^^^^^^^^^^^^^^^^^^^^
  File "C:\Users\91853\OneDrive\Desktop\tasks\aibee_social\env\Lib\site-packages\django\urls\conf.py", line 39, in include
    urlconf_module = import_module(urlconf_module)
                     ^^^^^^^^^^^^^^^^^^^^^^^^^^^^^
  File "C:\Users\91853\AppData\Local\Programs\Python\Python311\Lib\importlib\__init__.py", line 126, in import_module
    return _bootstrap._gcd_import(name[level:], package, level)
           ^^^^^^^^^^^^^^^^^^^^^^^^^^^^^^^^^^^^^^^^^^^^^^^^^^^^
  File "<frozen importlib._bootstrap>", line 1204, in _gcd_import
  File "<frozen importlib._bootstrap>", line 1176, in _find_and_load
  File "<frozen importlib._bootstrap>", line 1147, in _find_and_load_unlocked
  File "<frozen importlib._bootstrap>", line 690, in _load_unlocked
  File "<frozen importlib._bootstrap_external>", line 940, in exec_module
  File "<frozen importlib._bootstrap>", line 241, in _call_with_frames_removed
  File "C:\Users\91853\OneDrive\Desktop\tasks\aibee_social\business\urls.py", line 1, in <module>
    from business.views import (BusinessDetailsListCreate,BusinessProfileQuestionnaire,CommunicationPreferences,CommunicationStyle,
  File "C:\Users\91853\OneDrive\Desktop\tasks\aibee_social\business\views.py", line 2, in <module>
    from .serializers import (BusinessDetailsSerializer,BusinessProfileQuestionnaireSerializer,CommunicationPreferencesSerializer,
  File "C:\Users\91853\OneDrive\Desktop\tasks\aibee_social\business\serializers.py", line 3, in <module>
    from .models import (
ImportError: cannot import name 'contenttypes' from 'business.models' (C:\Users\91853\OneDrive\Desktop\tasks\aibee_social\business\models.py)
C:\Users\91853\OneDrive\Desktop\tasks\aibee_social\business\serializers.py changed, reloading.
DB_NAME socialdb
Performing system checks...

Watching for file changes with StatReloader
Exception in thread django-main-thread:
Traceback (most recent call last):
  File "C:\Users\91853\OneDrive\Desktop\tasks\aibee_social\env\Lib\site-packages\django\core\checks\urls.py", line 136, in check_custom_error_handlers
    handler = resolver.resolve_error_handler(status_code)
              ^^^^^^^^^^^^^^^^^^^^^^^^^^^^^^^^^^^^^^^^^^^
  File "C:\Users\91853\OneDrive\Desktop\tasks\aibee_social\env\Lib\site-packages\django\urls\resolvers.py", line 732, in resolve_error_handler
    callback = getattr(self.urlconf_module, "handler%s" % view_type, None)
                       ^^^^^^^^^^^^^^^^^^^
  File "C:\Users\91853\OneDrive\Desktop\tasks\aibee_social\env\Lib\site-packages\django\utils\functional.py", line 47, in __get__
    res = instance.__dict__[self.name] = self.func(instance)
                                         ^^^^^^^^^^^^^^^^^^^
  File "C:\Users\91853\OneDrive\Desktop\tasks\aibee_social\env\Lib\site-packages\django\urls\resolvers.py", line 711, in urlconf_module
    return import_module(self.urlconf_name)
           ^^^^^^^^^^^^^^^^^^^^^^^^^^^^^^^^
  File "C:\Users\91853\AppData\Local\Programs\Python\Python311\Lib\importlib\__init__.py", line 126, in import_module
    return _bootstrap._gcd_import(name[level:], package, level)
           ^^^^^^^^^^^^^^^^^^^^^^^^^^^^^^^^^^^^^^^^^^^^^^^^^^^^
  File "<frozen importlib._bootstrap>", line 1204, in _gcd_import
  File "<frozen importlib._bootstrap>", line 1176, in _find_and_load
  File "<frozen importlib._bootstrap>", line 1147, in _find_and_load_unlocked
  File "<frozen importlib._bootstrap>", line 690, in _load_unlocked
  File "<frozen importlib._bootstrap_external>", line 940, in exec_module
  File "<frozen importlib._bootstrap>", line 241, in _call_with_frames_removed
  File "C:\Users\91853\OneDrive\Desktop\tasks\aibee_social\aibee_social\urls.py", line 23, in <module>
    path('api/business/',include ('business.urls')),
                         ^^^^^^^^^^^^^^^^^^^^^^^^^
  File "C:\Users\91853\OneDrive\Desktop\tasks\aibee_social\env\Lib\site-packages\django\urls\conf.py", line 39, in include
    urlconf_module = import_module(urlconf_module)
                     ^^^^^^^^^^^^^^^^^^^^^^^^^^^^^
  File "C:\Users\91853\AppData\Local\Programs\Python\Python311\Lib\importlib\__init__.py", line 126, in import_module
    return _bootstrap._gcd_import(name[level:], package, level)
           ^^^^^^^^^^^^^^^^^^^^^^^^^^^^^^^^^^^^^^^^^^^^^^^^^^^^
  File "<frozen importlib._bootstrap>", line 1204, in _gcd_import
  File "<frozen importlib._bootstrap>", line 1176, in _find_and_load
  File "<frozen importlib._bootstrap>", line 1147, in _find_and_load_unlocked
  File "<frozen importlib._bootstrap>", line 690, in _load_unlocked
  File "<frozen importlib._bootstrap_external>", line 940, in exec_module
  File "<frozen importlib._bootstrap>", line 241, in _call_with_frames_removed
  File "C:\Users\91853\OneDrive\Desktop\tasks\aibee_social\business\urls.py", line 1, in <module>
    from business.views import (BusinessDetailsListCreate,BusinessProfileQuestionnaire,CommunicationPreferences,CommunicationStyle,
  File "C:\Users\91853\OneDrive\Desktop\tasks\aibee_social\business\views.py", line 2, in <module>
    from .serializers import (BusinessDetailsSerializer,BusinessProfileQuestionnaireSerializer,CommunicationPreferencesSerializer,
  File "C:\Users\91853\OneDrive\Desktop\tasks\aibee_social\business\serializers.py", line 3, in <module>
    from .models import (
ImportError: cannot import name 'successMetrics' from 'business.models' (C:\Users\91853\OneDrive\Desktop\tasks\aibee_social\business\models.py)

During handling of the above exception, another exception occurred:

Traceback (most recent call last):
  File "C:\Users\91853\AppData\Local\Programs\Python\Python311\Lib\threading.py", line 1038, in _bootstrap_inner
    self.run()
  File "C:\Users\91853\AppData\Local\Programs\Python\Python311\Lib\threading.py", line 975, in run
    self._target(*self._args, **self._kwargs)
  File "C:\Users\91853\OneDrive\Desktop\tasks\aibee_social\env\Lib\site-packages\django\utils\autoreload.py", line 64, in wrapper
    fn(*args, **kwargs)
  File "C:\Users\91853\OneDrive\Desktop\tasks\aibee_social\env\Lib\site-packages\django\core\management\commands\runserver.py", line 134, in inner_run
    self.check(display_num_errors=True)
  File "C:\Users\91853\OneDrive\Desktop\tasks\aibee_social\env\Lib\site-packages\django\core\management\base.py", line 486, in check
    all_issues = checks.run_checks(
                 ^^^^^^^^^^^^^^^^^^
  File "C:\Users\91853\OneDrive\Desktop\tasks\aibee_social\env\Lib\site-packages\django\core\checks\registry.py", line 88, in run_checks
    new_errors = check(app_configs=app_configs, databases=databases)
                 ^^^^^^^^^^^^^^^^^^^^^^^^^^^^^^^^^^^^^^^^^^^^^^^^^^^
  File "C:\Users\91853\OneDrive\Desktop\tasks\aibee_social\env\Lib\site-packages\django\core\checks\urls.py", line 138, in check_custom_error_handlers
    path = getattr(resolver.urlconf_module, "handler%s" % status_code)
                   ^^^^^^^^^^^^^^^^^^^^^^^
  File "C:\Users\91853\OneDrive\Desktop\tasks\aibee_social\env\Lib\site-packages\django\utils\functional.py", line 47, in __get__
    res = instance.__dict__[self.name] = self.func(instance)
                                         ^^^^^^^^^^^^^^^^^^^
  File "C:\Users\91853\OneDrive\Desktop\tasks\aibee_social\env\Lib\site-packages\django\urls\resolvers.py", line 711, in urlconf_module
    return import_module(self.urlconf_name)
           ^^^^^^^^^^^^^^^^^^^^^^^^^^^^^^^^
  File "C:\Users\91853\AppData\Local\Programs\Python\Python311\Lib\importlib\__init__.py", line 126, in import_module
    return _bootstrap._gcd_import(name[level:], package, level)
           ^^^^^^^^^^^^^^^^^^^^^^^^^^^^^^^^^^^^^^^^^^^^^^^^^^^^
  File "<frozen importlib._bootstrap>", line 1204, in _gcd_import
  File "<frozen importlib._bootstrap>", line 1176, in _find_and_load
  File "<frozen importlib._bootstrap>", line 1147, in _find_and_load_unlocked
  File "<frozen importlib._bootstrap>", line 690, in _load_unlocked
  File "<frozen importlib._bootstrap_external>", line 940, in exec_module
  File "<frozen importlib._bootstrap>", line 241, in _call_with_frames_removed
  File "C:\Users\91853\OneDrive\Desktop\tasks\aibee_social\aibee_social\urls.py", line 23, in <module>
    path('api/business/',include ('business.urls')),
                         ^^^^^^^^^^^^^^^^^^^^^^^^^
  File "C:\Users\91853\OneDrive\Desktop\tasks\aibee_social\env\Lib\site-packages\django\urls\conf.py", line 39, in include
    urlconf_module = import_module(urlconf_module)
                     ^^^^^^^^^^^^^^^^^^^^^^^^^^^^^
  File "C:\Users\91853\AppData\Local\Programs\Python\Python311\Lib\importlib\__init__.py", line 126, in import_module
    return _bootstrap._gcd_import(name[level:], package, level)
           ^^^^^^^^^^^^^^^^^^^^^^^^^^^^^^^^^^^^^^^^^^^^^^^^^^^^
  File "<frozen importlib._bootstrap>", line 1204, in _gcd_import
  File "<frozen importlib._bootstrap>", line 1176, in _find_and_load
  File "<frozen importlib._bootstrap>", line 1147, in _find_and_load_unlocked
  File "<frozen importlib._bootstrap>", line 690, in _load_unlocked
  File "<frozen importlib._bootstrap_external>", line 940, in exec_module
  File "<frozen importlib._bootstrap>", line 241, in _call_with_frames_removed
  File "C:\Users\91853\OneDrive\Desktop\tasks\aibee_social\business\urls.py", line 1, in <module>
    from business.views import (BusinessDetailsListCreate,BusinessProfileQuestionnaire,CommunicationPreferences,CommunicationStyle,
  File "C:\Users\91853\OneDrive\Desktop\tasks\aibee_social\business\views.py", line 2, in <module>
    from .serializers import (BusinessDetailsSerializer,BusinessProfileQuestionnaireSerializer,CommunicationPreferencesSerializer,
  File "C:\Users\91853\OneDrive\Desktop\tasks\aibee_social\business\serializers.py", line 3, in <module>
    from .models import (
ImportError: cannot import name 'successMetrics' from 'business.models' (C:\Users\91853\OneDrive\Desktop\tasks\aibee_social\business\models.py)
C:\Users\91853\OneDrive\Desktop\tasks\aibee_social\business\serializers.py changed, reloading.
DB_NAME socialdb
Performing system checks...

Watching for file changes with StatReloader
Exception in thread django-main-thread:
Traceback (most recent call last):
  File "C:\Users\91853\OneDrive\Desktop\tasks\aibee_social\env\Lib\site-packages\django\core\checks\urls.py", line 136, in check_custom_error_handlers
    handler = resolver.resolve_error_handler(status_code)
              ^^^^^^^^^^^^^^^^^^^^^^^^^^^^^^^^^^^^^^^^^^^
  File "C:\Users\91853\OneDrive\Desktop\tasks\aibee_social\env\Lib\site-packages\django\urls\resolvers.py", line 732, in resolve_error_handler
    callback = getattr(self.urlconf_module, "handler%s" % view_type, None)
                       ^^^^^^^^^^^^^^^^^^^
  File "C:\Users\91853\OneDrive\Desktop\tasks\aibee_social\env\Lib\site-packages\django\utils\functional.py", line 47, in __get__
    res = instance.__dict__[self.name] = self.func(instance)
                                         ^^^^^^^^^^^^^^^^^^^
  File "C:\Users\91853\OneDrive\Desktop\tasks\aibee_social\env\Lib\site-packages\django\urls\resolvers.py", line 711, in urlconf_module
    return import_module(self.urlconf_name)
           ^^^^^^^^^^^^^^^^^^^^^^^^^^^^^^^^
  File "C:\Users\91853\AppData\Local\Programs\Python\Python311\Lib\importlib\__init__.py", line 126, in import_module
    return _bootstrap._gcd_import(name[level:], package, level)
           ^^^^^^^^^^^^^^^^^^^^^^^^^^^^^^^^^^^^^^^^^^^^^^^^^^^^
  File "<frozen importlib._bootstrap>", line 1204, in _gcd_import
  File "<frozen importlib._bootstrap>", line 1176, in _find_and_load
  File "<frozen importlib._bootstrap>", line 1147, in _find_and_load_unlocked
  File "<frozen importlib._bootstrap>", line 690, in _load_unlocked
  File "<frozen importlib._bootstrap_external>", line 940, in exec_module
  File "<frozen importlib._bootstrap>", line 241, in _call_with_frames_removed
  File "C:\Users\91853\OneDrive\Desktop\tasks\aibee_social\aibee_social\urls.py", line 23, in <module>
    path('api/business/',include ('business.urls')),
                         ^^^^^^^^^^^^^^^^^^^^^^^^^
  File "C:\Users\91853\OneDrive\Desktop\tasks\aibee_social\env\Lib\site-packages\django\urls\conf.py", line 39, in include
    urlconf_module = import_module(urlconf_module)
                     ^^^^^^^^^^^^^^^^^^^^^^^^^^^^^
  File "C:\Users\91853\AppData\Local\Programs\Python\Python311\Lib\importlib\__init__.py", line 126, in import_module
    return _bootstrap._gcd_import(name[level:], package, level)
           ^^^^^^^^^^^^^^^^^^^^^^^^^^^^^^^^^^^^^^^^^^^^^^^^^^^^
  File "<frozen importlib._bootstrap>", line 1204, in _gcd_import
  File "<frozen importlib._bootstrap>", line 1176, in _find_and_load
  File "<frozen importlib._bootstrap>", line 1147, in _find_and_load_unlocked
  File "<frozen importlib._bootstrap>", line 690, in _load_unlocked
  File "<frozen importlib._bootstrap_external>", line 940, in exec_module
  File "<frozen importlib._bootstrap>", line 241, in _call_with_frames_removed
  File "C:\Users\91853\OneDrive\Desktop\tasks\aibee_social\business\urls.py", line 1, in <module>
    from business.views import (BusinessDetailsListCreate,BusinessProfileQuestionnaire,CommunicationPreferences,CommunicationStyle,
  File "C:\Users\91853\OneDrive\Desktop\tasks\aibee_social\business\views.py", line 2, in <module>
    from .serializers import (BusinessDetailsSerializer,BusinessProfileQuestionnaireSerializer,CommunicationPreferencesSerializer,
  File "C:\Users\91853\OneDrive\Desktop\tasks\aibee_social\business\serializers.py", line 3, in <module>
    from .models import (
ImportError: cannot import name 'successMetrics' from 'business.models' (C:\Users\91853\OneDrive\Desktop\tasks\aibee_social\business\models.py)

During handling of the above exception, another exception occurred:

Traceback (most recent call last):
  File "C:\Users\91853\AppData\Local\Programs\Python\Python311\Lib\threading.py", line 1038, in _bootstrap_inner
    self.run()
  File "C:\Users\91853\AppData\Local\Programs\Python\Python311\Lib\threading.py", line 975, in run
    self._target(*self._args, **self._kwargs)
  File "C:\Users\91853\OneDrive\Desktop\tasks\aibee_social\env\Lib\site-packages\django\utils\autoreload.py", line 64, in wrapper
    fn(*args, **kwargs)
  File "C:\Users\91853\OneDrive\Desktop\tasks\aibee_social\env\Lib\site-packages\django\core\management\commands\runserver.py", line 134, in inner_run
    self.check(display_num_errors=True)
  File "C:\Users\91853\OneDrive\Desktop\tasks\aibee_social\env\Lib\site-packages\django\core\management\base.py", line 486, in check
    all_issues = checks.run_checks(
                 ^^^^^^^^^^^^^^^^^^
  File "C:\Users\91853\OneDrive\Desktop\tasks\aibee_social\env\Lib\site-packages\django\core\checks\registry.py", line 88, in run_checks
    new_errors = check(app_configs=app_configs, databases=databases)
                 ^^^^^^^^^^^^^^^^^^^^^^^^^^^^^^^^^^^^^^^^^^^^^^^^^^^
  File "C:\Users\91853\OneDrive\Desktop\tasks\aibee_social\env\Lib\site-packages\django\core\checks\urls.py", line 138, in check_custom_error_handlers
    path = getattr(resolver.urlconf_module, "handler%s" % status_code)
                   ^^^^^^^^^^^^^^^^^^^^^^^
  File "C:\Users\91853\OneDrive\Desktop\tasks\aibee_social\env\Lib\site-packages\django\utils\functional.py", line 47, in __get__
    res = instance.__dict__[self.name] = self.func(instance)
                                         ^^^^^^^^^^^^^^^^^^^
  File "C:\Users\91853\OneDrive\Desktop\tasks\aibee_social\env\Lib\site-packages\django\urls\resolvers.py", line 711, in urlconf_module
    return import_module(self.urlconf_name)
           ^^^^^^^^^^^^^^^^^^^^^^^^^^^^^^^^
  File "C:\Users\91853\AppData\Local\Programs\Python\Python311\Lib\importlib\__init__.py", line 126, in import_module
    return _bootstrap._gcd_import(name[level:], package, level)
           ^^^^^^^^^^^^^^^^^^^^^^^^^^^^^^^^^^^^^^^^^^^^^^^^^^^^
  File "<frozen importlib._bootstrap>", line 1204, in _gcd_import
  File "<frozen importlib._bootstrap>", line 1176, in _find_and_load
  File "<frozen importlib._bootstrap>", line 1147, in _find_and_load_unlocked
  File "<frozen importlib._bootstrap>", line 690, in _load_unlocked
  File "<frozen importlib._bootstrap_external>", line 940, in exec_module
  File "<frozen importlib._bootstrap>", line 241, in _call_with_frames_removed
  File "C:\Users\91853\OneDrive\Desktop\tasks\aibee_social\aibee_social\urls.py", line 23, in <module>
    path('api/business/',include ('business.urls')),
                         ^^^^^^^^^^^^^^^^^^^^^^^^^
  File "C:\Users\91853\OneDrive\Desktop\tasks\aibee_social\env\Lib\site-packages\django\urls\conf.py", line 39, in include
    urlconf_module = import_module(urlconf_module)
                     ^^^^^^^^^^^^^^^^^^^^^^^^^^^^^
  File "C:\Users\91853\AppData\Local\Programs\Python\Python311\Lib\importlib\__init__.py", line 126, in import_module
    return _bootstrap._gcd_import(name[level:], package, level)
           ^^^^^^^^^^^^^^^^^^^^^^^^^^^^^^^^^^^^^^^^^^^^^^^^^^^^
  File "<frozen importlib._bootstrap>", line 1204, in _gcd_import
  File "<frozen importlib._bootstrap>", line 1176, in _find_and_load
  File "<frozen importlib._bootstrap>", line 1147, in _find_and_load_unlocked
  File "<frozen importlib._bootstrap>", line 690, in _load_unlocked
  File "<frozen importlib._bootstrap_external>", line 940, in exec_module
  File "<frozen importlib._bootstrap>", line 241, in _call_with_frames_removed
  File "C:\Users\91853\OneDrive\Desktop\tasks\aibee_social\business\urls.py", line 1, in <module>
    from business.views import (BusinessDetailsListCreate,BusinessProfileQuestionnaire,CommunicationPreferences,CommunicationStyle,
  File "C:\Users\91853\OneDrive\Desktop\tasks\aibee_social\business\views.py", line 2, in <module>
    from .serializers import (BusinessDetailsSerializer,BusinessProfileQuestionnaireSerializer,CommunicationPreferencesSerializer,
  File "C:\Users\91853\OneDrive\Desktop\tasks\aibee_social\business\serializers.py", line 3, in <module>
    from .models import (
ImportError: cannot import name 'successMetrics' from 'business.models' (C:\Users\91853\OneDrive\Desktop\tasks\aibee_social\business\models.py)
C:\Users\91853\OneDrive\Desktop\tasks\aibee_social\business\serializers.py changed, reloading.
DB_NAME socialdb
Performing system checks...

Watching for file changes with StatReloader
C:\Users\91853\OneDrive\Desktop\tasks\aibee_social\business\views.py changed, reloading.
DB_NAME socialdb
Performing system checks...

System check identified no issues (0 silenced).
February 19, 2025 - 17:56:15
Django version 5.1.6, using settings 'aibee_social.settings'
Starting development server at http://0.0.0.0:8000/
Quit the server with CTRL-BREAK.

Watching for file changes with StatReloader
C:\Users\91853\OneDrive\Desktop\tasks\aibee_social\business\views.py changed, reloading.
DB_NAME socialdb
Performing system checks...

System check identified no issues (0 silenced).
February 19, 2025 - 17:59:38
Django version 5.1.6, using settings 'aibee_social.settings'
Starting development server at http://0.0.0.0:8000/
Quit the server with CTRL-BREAK.

Watching for file changes with StatReloader
C:\Users\91853\OneDrive\Desktop\tasks\aibee_social\business\views.py changed, reloading.
DB_NAME socialdb
Performing system checks...

System check identified no issues (0 silenced).
February 19, 2025 - 18:00:25
Django version 5.1.6, using settings 'aibee_social.settings'
Starting development server at http://0.0.0.0:8000/
Quit the server with CTRL-BREAK.

Watching for file changes with StatReloader
C:\Users\91853\OneDrive\Desktop\tasks\aibee_social\business\urls.py changed, reloading.
DB_NAME socialdb
Performing system checks...

System check identified no issues (0 silenced).
February 19, 2025 - 18:09:48
Django version 5.1.6, using settings 'aibee_social.settings'
Starting development server at http://0.0.0.0:8000/
Quit the server with CTRL-BREAK.

Watching for file changes with StatReloader
C:\Users\91853\OneDrive\Desktop\tasks\aibee_social\business\urls.py changed, reloading.
DB_NAME socialdb
Performing system checks...

System check identified no issues (0 silenced).
February 19, 2025 - 18:10:15
Django version 5.1.6, using settings 'aibee_social.settings'
Starting development server at http://0.0.0.0:8000/
Quit the server with CTRL-BREAK.

Watching for file changes with StatReloader
C:\Users\91853\OneDrive\Desktop\tasks\aibee_social\business\views.py changed, reloading.
DB_NAME socialdb
Performing system checks...

System check identified no issues (0 silenced).
February 19, 2025 - 18:12:34
Django version 5.1.6, using settings 'aibee_social.settings'
Starting development server at http://0.0.0.0:8000/
Quit the server with CTRL-BREAK.

Watching for file changes with StatReloader
C:\Users\91853\OneDrive\Desktop\tasks\aibee_social\business\views.py changed, reloading.
DB_NAME socialdb
Performing system checks...

System check identified no issues (0 silenced).
February 19, 2025 - 18:12:57
Django version 5.1.6, using settings 'aibee_social.settings'
Starting development server at http://0.0.0.0:8000/
Quit the server with CTRL-BREAK.

Watching for file changes with StatReloader
C:\Users\91853\OneDrive\Desktop\tasks\aibee_social\business\views.py changed, reloading.
DB_NAME socialdb
Performing system checks...

System check identified no issues (0 silenced).
February 19, 2025 - 18:19:34
Django version 5.1.6, using settings 'aibee_social.settings'
Starting development server at http://0.0.0.0:8000/
Quit the server with CTRL-BREAK.

Watching for file changes with StatReloader
C:\Users\91853\OneDrive\Desktop\tasks\aibee_social\business\views.py changed, reloading.
DB_NAME socialdb
Performing system checks...

System check identified no issues (0 silenced).
February 19, 2025 - 18:56:49
Django version 5.1.6, using settings 'aibee_social.settings'
Starting development server at http://0.0.0.0:8000/
Quit the server with CTRL-BREAK.

Watching for file changes with StatReloader
C:\Users\91853\OneDrive\Desktop\tasks\aibee_social\business\urls.py changed, reloading.
DB_NAME socialdb
Performing system checks...

System check identified no issues (0 silenced).
February 19, 2025 - 18:58:38
Django version 5.1.6, using settings 'aibee_social.settings'
Starting development server at http://0.0.0.0:8000/
Quit the server with CTRL-BREAK.

Watching for file changes with StatReloader
C:\Users\91853\OneDrive\Desktop\tasks\aibee_social\business\views.py changed, reloading.
DB_NAME socialdb
Performing system checks...

System check identified no issues (0 silenced).
February 19, 2025 - 18:59:24
Django version 5.1.6, using settings 'aibee_social.settings'
Starting development server at http://0.0.0.0:8000/
Quit the server with CTRL-BREAK.

Watching for file changes with StatReloader
C:\Users\91853\OneDrive\Desktop\tasks\aibee_social\business\views.py changed, reloading.
DB_NAME socialdb
Performing system checks...

System check identified no issues (0 silenced).
February 19, 2025 - 19:01:15
Django version 5.1.6, using settings 'aibee_social.settings'
Starting development server at http://0.0.0.0:8000/
Quit the server with CTRL-BREAK.

Watching for file changes with StatReloader
C:\Users\91853\OneDrive\Desktop\tasks\aibee_social\business\views.py changed, reloading.
DB_NAME socialdb
Performing system checks...

System check identified no issues (0 silenced).
February 19, 2025 - 19:01:30
Django version 5.1.6, using settings 'aibee_social.settings'
Starting development server at http://0.0.0.0:8000/
Quit the server with CTRL-BREAK.

Watching for file changes with StatReloader
C:\Users\91853\OneDrive\Desktop\tasks\aibee_social\business\views.py changed, reloading.
DB_NAME socialdb
Performing system checks...

System check identified no issues (0 silenced).
February 19, 2025 - 19:02:56
Django version 5.1.6, using settings 'aibee_social.settings'
Starting development server at http://0.0.0.0:8000/
Quit the server with CTRL-BREAK.

Watching for file changes with StatReloader
C:\Users\91853\OneDrive\Desktop\tasks\aibee_social\business\views.py changed, reloading.
DB_NAME socialdb
Performing system checks...

System check identified no issues (0 silenced).
February 19, 2025 - 19:03:38
Django version 5.1.6, using settings 'aibee_social.settings'
Starting development server at http://0.0.0.0:8000/
Quit the server with CTRL-BREAK.

Watching for file changes with StatReloader
C:\Users\91853\OneDrive\Desktop\tasks\aibee_social\business\views.py changed, reloading.
DB_NAME socialdb
Performing system checks...

System check identified no issues (0 silenced).
February 19, 2025 - 19:03:56
Django version 5.1.6, using settings 'aibee_social.settings'
Starting development server at http://0.0.0.0:8000/
Quit the server with CTRL-BREAK.

Watching for file changes with StatReloader
C:\Users\91853\OneDrive\Desktop\tasks\aibee_social\business\views.py changed, reloading.
DB_NAME socialdb
Performing system checks...

System check identified no issues (0 silenced).
February 19, 2025 - 19:04:42
Django version 5.1.6, using settings 'aibee_social.settings'
Starting development server at http://0.0.0.0:8000/
Quit the server with CTRL-BREAK.

Watching for file changes with StatReloader
C:\Users\91853\OneDrive\Desktop\tasks\aibee_social\business\views.py changed, reloading.
DB_NAME socialdb
Performing system checks...

System check identified no issues (0 silenced).
February 19, 2025 - 19:06:12
Django version 5.1.6, using settings 'aibee_social.settings'
Starting development server at http://0.0.0.0:8000/
Quit the server with CTRL-BREAK.

Watching for file changes with StatReloader
C:\Users\91853\OneDrive\Desktop\tasks\aibee_social\business\views.py changed, reloading.
DB_NAME socialdb
Performing system checks...

System check identified no issues (0 silenced).
February 19, 2025 - 19:11:22
Django version 5.1.6, using settings 'aibee_social.settings'
Starting development server at http://0.0.0.0:8000/
Quit the server with CTRL-BREAK.

Watching for file changes with StatReloader
C:\Users\91853\OneDrive\Desktop\tasks\aibee_social\business\views.py changed, reloading.
DB_NAME socialdb
Performing system checks...

System check identified no issues (0 silenced).
February 19, 2025 - 19:11:49
Django version 5.1.6, using settings 'aibee_social.settings'
Starting development server at http://0.0.0.0:8000/
Quit the server with CTRL-BREAK.

Watching for file changes with StatReloader
C:\Users\91853\OneDrive\Desktop\tasks\aibee_social\business\views.py changed, reloading.
DB_NAME socialdb
Performing system checks...

System check identified no issues (0 silenced).
February 19, 2025 - 19:12:11
Django version 5.1.6, using settings 'aibee_social.settings'
Starting development server at http://0.0.0.0:8000/
Quit the server with CTRL-BREAK.

Watching for file changes with StatReloader
C:\Users\91853\OneDrive\Desktop\tasks\aibee_social\business\views.py changed, reloading.
DB_NAME socialdb
Performing system checks...

System check identified no issues (0 silenced).
February 19, 2025 - 19:12:33
Django version 5.1.6, using settings 'aibee_social.settings'
Starting development server at http://0.0.0.0:8000/
Quit the server with CTRL-BREAK.

Watching for file changes with StatReloader
C:\Users\91853\OneDrive\Desktop\tasks\aibee_social\business\views.py changed, reloading.
DB_NAME socialdb
Performing system checks...

System check identified no issues (0 silenced).
February 19, 2025 - 19:12:38
Django version 5.1.6, using settings 'aibee_social.settings'
Starting development server at http://0.0.0.0:8000/
Quit the server with CTRL-BREAK.

Watching for file changes with StatReloader
C:\Users\91853\OneDrive\Desktop\tasks\aibee_social\business\views.py changed, reloading.
DB_NAME socialdb
Performing system checks...

System check identified no issues (0 silenced).
February 19, 2025 - 19:13:07
Django version 5.1.6, using settings 'aibee_social.settings'
Starting development server at http://0.0.0.0:8000/
Quit the server with CTRL-BREAK.

Watching for file changes with StatReloader
C:\Users\91853\OneDrive\Desktop\tasks\aibee_social\business\views.py changed, reloading.
DB_NAME socialdb
Performing system checks...

System check identified no issues (0 silenced).
February 19, 2025 - 19:13:19
Django version 5.1.6, using settings 'aibee_social.settings'
Starting development server at http://0.0.0.0:8000/
Quit the server with CTRL-BREAK.

Watching for file changes with StatReloader
C:\Users\91853\OneDrive\Desktop\tasks\aibee_social\business\views.py changed, reloading.
DB_NAME socialdb
Performing system checks...

System check identified no issues (0 silenced).
February 19, 2025 - 19:16:37
Django version 5.1.6, using settings 'aibee_social.settings'
Starting development server at http://0.0.0.0:8000/
Quit the server with CTRL-BREAK.

Watching for file changes with StatReloader
C:\Users\91853\OneDrive\Desktop\tasks\aibee_social\business\views.py changed, reloading.
DB_NAME socialdb
Performing system checks...

System check identified no issues (0 silenced).
February 19, 2025 - 19:47:36
Django version 5.1.6, using settings 'aibee_social.settings'
Starting development server at http://0.0.0.0:8000/
Quit the server with CTRL-BREAK.

Watching for file changes with StatReloader
C:\Users\91853\OneDrive\Desktop\tasks\aibee_social\business\views.py changed, reloading.
DB_NAME socialdb
Performing system checks...

System check identified no issues (0 silenced).
February 19, 2025 - 19:47:41
Django version 5.1.6, using settings 'aibee_social.settings'
Starting development server at http://0.0.0.0:8000/
Quit the server with CTRL-BREAK.

Watching for file changes with StatReloader
C:\Users\91853\OneDrive\Desktop\tasks\aibee_social\business\views.py changed, reloading.
DB_NAME socialdb
Performing system checks...

System check identified no issues (0 silenced).
February 19, 2025 - 19:49:13
Django version 5.1.6, using settings 'aibee_social.settings'
Starting development server at http://0.0.0.0:8000/
Quit the server with CTRL-BREAK.

Watching for file changes with StatReloader
C:\Users\91853\OneDrive\Desktop\tasks\aibee_social\aibee_social\settings.py changed, reloading.
DB_NAME socialdb
Performing system checks...

System check identified no issues (0 silenced).
February 19, 2025 - 19:53:20
Django version 5.1.6, using settings 'aibee_social.settings'
Starting development server at http://0.0.0.0:8000/
Quit the server with CTRL-BREAK.

Watching for file changes with StatReloader
C:\Users\91853\OneDrive\Desktop\tasks\aibee_social\business\migrations\0001_initial.py changed, reloading.
DB_NAME socialdb
Performing system checks...

System check identified no issues (0 silenced).
February 19, 2025 - 19:58:16
Django version 5.1.6, using settings 'aibee_social.settings'
Starting development server at http://0.0.0.0:8000/
Quit the server with CTRL-BREAK.

Watching for file changes with StatReloader
C:\Users\91853\OneDrive\Desktop\tasks\aibee_social\business\migrations\0001_initial.py changed, reloading.
DB_NAME socialdb
Performing system checks...

System check identified no issues (0 silenced).
February 19, 2025 - 20:01:00
Django version 5.1.6, using settings 'aibee_social.settings'
Starting development server at http://0.0.0.0:8000/
Quit the server with CTRL-BREAK.

Watching for file changes with StatReloader
